Workbook

Sheet 說明
B2: TOMS 雙週 PJT 差異（2026 / 2027）
B3: 每週三由 Carrie 更新，比較本週與前期（兩週前）的 BIS 資料
B5: 報告日期 | C5: 46302 | D5: 本週 BIS 撈取日期（每週三）
B6: 比較基準日期 | C6: 46288 | D6: 前期 BIS 撈取日期（兩週前的週三）
B7: 標打差異門檻 | C7: 3000 | D7: 任一 Program、任一期間的標打增減達此數量，就標示「需說明」。預設 3,000 標打 = 0.3 萬
B8: NCMT 差異門檻 | C8: 0.3 | D8: NCMT（成改後）增減達此金額，也標示「需說明」
B9: 填表人 | C9: Carrie
B11: 每週操作步驟
B12: 1. 從 BIS 撈取 TOMS 2026、2027 兩張表（與本檔附的格式相同）。
B13: 2. 把「前期_2026」「前期_2027」換成兩週前的 BIS 資料：整張貼到 A1。（通常就是兩週前那份檔案的「本週」頁）
B14: 3. 把本週撈的資料整張貼到「本週_2026」「本週_2027」的 A1。欄位順序或月份欄變多都沒關係，公式會自己找「2026」「2026-Q1」等欄名。
B15: 4. 更新上方黃色格的報告日期、比較基準日期。
B16: 5. 到「差異明細」頁，用篩選只看「需說明」的列，填寫黃色的「原因」（下拉選單）和「說明」。
B17: 6. 「主管報告」頁會自動更新，可直接列印、轉 PDF，或截圖貼進每週三的信。
B18: 7. 另存新檔，檔名建議：TOMS_雙週差_YYYYMMDD.xlsx。下週再用時，清空「原因」「說明」兩欄。
B20: 顏色說明
B21: 黃底藍字 | C21: 需要手動填寫的格子
B22: 橘底 | C22: 差異超過門檻、需要說明的列
B23: 白底黑字 | C23: 公式自動計算，請勿修改
B25: 填寫範例
B26: 欄位 | C26: 範例內容
B27: Program | C27: YEARLY RUN-ACT300
B28: 期間 | C28: 2026-Q3（同時 2026-Q4 也有反向差異）
B29: 差異標打 | C29: −57,000（Q4 為 +57,000）
B30: 原因 | C30: 季別移動
B31: 說明 | C31: 客戶 9 月出貨延到 10 月，全年總量不變（此列為格式範例，非實際資料）
B33: 資料來源：BIS 撈取之 TOMS 2026、2027 PJT（標打、NET_CMT_標打_成改後），由 Joyce 提供格式。

Sheet 主管報告
A1: TOMS 雙週 PJT 差異報告
A2: ="報告日 "&TEXT(說明!$C$5,"yyyy/mm/dd")&"（比較基準 "&TEXT(說明!$C$6,"yyyy/mm/dd")&"） ｜ 填表："&說明!$C$9 -> 報告日 2026/10/07（比較基準 2026/09/23） ｜ 填表：Carrie
A4: 一、總覽（All Program）
A5: 年度 | B5: 本週標打 | C5: 前期標打 | D5: 差異標打 | E5: 差異% | F5: 本週NCMT | G5: 前期NCMT | H5: 差異NCMT
A6: 2026 | B6: =SUMIFS(差異明細!$E:$E,差異明細!$A:$A,2026,差異明細!$B:$B,"All Program",差異明細!$C:$C,2026) -> 988688.2 | C6: =SUMIFS(差異明細!$F:$F,差異明細!$A:$A,2026,差異明細!$B:$B,"All Program",差異明細!$C:$C,2026) -> 988688.2 | D6: =B6-C6 -> 0 | E6: =IF(C6=0,"",D6/C6) -> 0 | F6: =SUMIFS(差異明細!$I:$I,差異明細!$A:$A,2026,差異明細!$B:$B,"All Program",差異明細!$C:$C,2026) -> 19.16 | G6: =SUMIFS(差異明細!$J:$J,差異明細!$A:$A,2026,差異明細!$B:$B,"All Program",差異明細!$C:$C,2026) -> 19.16 | H6: =F6-G6 -> 0
A7: 2027 | B7: =SUMIFS(差異明細!$E:$E,差異明細!$A:$A,2027,差異明細!$B:$B,"All Program",差異明細!$C:$C,2027) -> 884101.9 | C7: =SUMIFS(差異明細!$F:$F,差異明細!$A:$A,2027,差異明細!$B:$B,"All Program",差異明細!$C:$C,2027) -> 884101.9 | D7: =B7-C7 -> 0 | E7: =IF(C7=0,"",D7/C7) -> 0 | F7: =SUMIFS(差異明細!$I:$I,差異明細!$A:$A,2027,差異明細!$B:$B,"All Program",差異明細!$C:$C,2027) -> 18.75 | G7: =SUMIFS(差異明細!$J:$J,差異明細!$A:$A,2027,差異明細!$B:$B,"All Program",差異明細!$C:$C,2027) -> 18.75 | H7: =F7-G7 -> 0
A9: 二、2026 雙週差（標打，單位：萬）
A10: Program | B10: 2026 | C10: 2026-Q1 | D10: 2026-Q2 | E10: 2026-Q3 | F10: 2026-Q4 | G10: 本週全年(萬) | H10: NCMT差異
A11: 總計 | B11: =SUMIFS(差異明細!$G:$G,差異明細!$A:$A,2026,差異明細!$B:$B,"All Program",差異明細!$C:$C,2026)/10000 -> 0 | C11: =SUMIFS(差異明細!$G:$G,差異明細!$A:$A,2026,差異明細!$B:$B,"All Program",差異明細!$C:$C,"2026-Q1")/10000 -> 0 | D11: =SUMIFS(差異明細!$G:$G,差異明細!$A:$A,2026,差異明細!$B:$B,"All Program",差異明細!$C:$C,"2026-Q2")/10000 -> 0 | E11: =SUMIFS(差異明細!$G:$G,差異明細!$A:$A,2026,差異明細!$B:$B,"All Program",差異明細!$C:$C,"2026-Q3")/10000 -> 0 | F11: =SUMIFS(差異明細!$G:$G,差異明細!$A:$A,2026,差異明細!$B:$B,"All Program",差異明細!$C:$C,"2026-Q4")/10000 -> 0 | G11: =SUMIFS(差異明細!$E:$E,差異明細!$A:$A,2026,差異明細!$B:$B,"All Program",差異明細!$C:$C,2026)/10000 -> 98.86882 | H11: =SUMIFS(差異明細!$K:$K,差異明細!$A:$A,2026,差異明細!$B:$B,"All Program",差異明細!$C:$C,2026) -> 0
A12: SEASONAL | B12: =SUMIFS(差異明細!$G:$G,差異明細!$A:$A,2026,差異明細!$B:$B,"SEASONAL",差異明細!$C:$C,2026)/10000 -> 0 | C12: =SUMIFS(差異明細!$G:$G,差異明細!$A:$A,2026,差異明細!$B:$B,"SEASONAL",差異明細!$C:$C,"2026-Q1")/10000 -> 0 | D12: =SUMIFS(差異明細!$G:$G,差異明細!$A:$A,2026,差異明細!$B:$B,"SEASONAL",差異明細!$C:$C,"2026-Q2")/10000 -> 0 | E12: =SUMIFS(差異明細!$G:$G,差異明細!$A:$A,2026,差異明細!$B:$B,"SEASONAL",差異明細!$C:$C,"2026-Q3")/10000 -> 0 | F12: =SUMIFS(差異明細!$G:$G,差異明細!$A:$A,2026,差異明細!$B:$B,"SEASONAL",差異明細!$C:$C,"2026-Q4")/10000 -> 0 | G12: =SUMIFS(差異明細!$E:$E,差異明細!$A:$A,2026,差異明細!$B:$B,"SEASONAL",差異明細!$C:$C,2026)/10000 -> 6.68478 | H12: =SUMIFS(差異明細!$K:$K,差異明細!$A:$A,2026,差異明細!$B:$B,"SEASONAL",差異明細!$C:$C,2026) -> 0
A13: SEASONAL-SWEATER | B13: =SUMIFS(差異明細!$G:$G,差異明細!$A:$A,2026,差異明細!$B:$B,"SEASONAL-SWEATER",差異明細!$C:$C,2026)/10000 -> 0 | C13: =SUMIFS(差異明細!$G:$G,差異明細!$A:$A,2026,差異明細!$B:$B,"SEASONAL-SWEATER",差異明細!$C:$C,"2026-Q1")/10000 -> 0 | D13: =SUMIFS(差異明細!$G:$G,差異明細!$A:$A,2026,差異明細!$B:$B,"SEASONAL-SWEATER",差異明細!$C:$C,"2026-Q2")/10000 -> 0 | E13: =SUMIFS(差異明細!$G:$G,差異明細!$A:$A,2026,差異明細!$B:$B,"SEASONAL-SWEATER",差異明細!$C:$C,"2026-Q3")/10000 -> 0 | F13: =SUMIFS(差異明細!$G:$G,差異明細!$A:$A,2026,差異明細!$B:$B,"SEASONAL-SWEATER",差異明細!$C:$C,"2026-Q4")/10000 -> 0 | G13: =SUMIFS(差異明細!$E:$E,差異明細!$A:$A,2026,差異明細!$B:$B,"SEASONAL-SWEATER",差異明細!$C:$C,2026)/10000 -> 9.53931 | H13: =SUMIFS(差異明細!$K:$K,差異明細!$A:$A,2026,差異明細!$B:$B,"SEASONAL-SWEATER",差異明細!$C:$C,2026) -> 0
A14: YEARLY RUN-304ALT | B14: =SUMIFS(差異明細!$G:$G,差異明細!$A:$A,2026,差異明細!$B:$B,"YEARLY RUN-304ALT",差異明細!$C:$C,2026)/10000 -> 0 | C14: =SUMIFS(差異明細!$G:$G,差異明細!$A:$A,2026,差異明細!$B:$B,"YEARLY RUN-304ALT",差異明細!$C:$C,"2026-Q1")/10000 -> 0 | D14: =SUMIFS(差異明細!$G:$G,差異明細!$A:$A,2026,差異明細!$B:$B,"YEARLY RUN-304ALT",差異明細!$C:$C,"2026-Q2")/10000 -> 0 | E14: =SUMIFS(差異明細!$G:$G,差異明細!$A:$A,2026,差異明細!$B:$B,"YEARLY RUN-304ALT",差異明細!$C:$C,"2026-Q3")/10000 -> 0 | F14: =SUMIFS(差異明細!$G:$G,差異明細!$A:$A,2026,差異明細!$B:$B,"YEARLY RUN-304ALT",差異明細!$C:$C,"2026-Q4")/10000 -> 0 | G14: =SUMIFS(差異明細!$E:$E,差異明細!$A:$A,2026,差異明細!$B:$B,"YEARLY RUN-304ALT",差異明細!$C:$C,2026)/10000 -> 6.54958 | H14: =SUMIFS(差異明細!$K:$K,差異明細!$A:$A,2026,差異明細!$B:$B,"YEARLY RUN-304ALT",差異明細!$C:$C,2026) -> 0
A15: YEARLY RUN-ACT300 | B15: =SUMIFS(差異明細!$G:$G,差異明細!$A:$A,2026,差異明細!$B:$B,"YEARLY RUN-ACT300",差異明細!$C:$C,2026)/10000 -> 0 | C15: =SUMIFS(差異明細!$G:$G,差異明細!$A:$A,2026,差異明細!$B:$B,"YEARLY RUN-ACT300",差異明細!$C:$C,"2026-Q1")/10000 -> 0 | D15: =SUMIFS(差異明細!$G:$G,差異明細!$A:$A,2026,差異明細!$B:$B,"YEARLY RUN-ACT300",差異明細!$C:$C,"2026-Q2")/10000 -> 0 | E15: =SUMIFS(差異明細!$G:$G,差異明細!$A:$A,2026,差異明細!$B:$B,"YEARLY RUN-ACT300",差異明細!$C:$C,"2026-Q3")/10000 -> 0 | F15: =SUMIFS(差異明細!$G:$G,差異明細!$A:$A,2026,差異明細!$B:$B,"YEARLY RUN-ACT300",差異明細!$C:$C,"2026-Q4")/10000 -> 0 | G15: =SUMIFS(差異明細!$E:$E,差異明細!$A:$A,2026,差異明細!$B:$B,"YEARLY RUN-ACT300",差異明細!$C:$C,2026)/10000 -> 57.6887 | H15: =SUMIFS(差異明細!$K:$K,差異明細!$A:$A,2026,差異明細!$B:$B,"YEARLY RUN-ACT300",差異明細!$C:$C,2026) -> 0
A16: YEARLY RUN-AIT350 | B16: =SUMIFS(差異明細!$G:$G,差異明細!$A:$A,2026,差異明細!$B:$B,"YEARLY RUN-AIT350",差異明細!$C:$C,2026)/10000 -> 0 | C16: =SUMIFS(差異明細!$G:$G,差異明細!$A:$A,2026,差異明細!$B:$B,"YEARLY RUN-AIT350",差異明細!$C:$C,"2026-Q1")/10000 -> 0 | D16: =SUMIFS(差異明細!$G:$G,差異明細!$A:$A,2026,差異明細!$B:$B,"YEARLY RUN-AIT350",差異明細!$C:$C,"2026-Q2")/10000 -> 0 | E16: =SUMIFS(差異明細!$G:$G,差異明細!$A:$A,2026,差異明細!$B:$B,"YEARLY RUN-AIT350",差異明細!$C:$C,"2026-Q3")/10000 -> 0 | F16: =SUMIFS(差異明細!$G:$G,差異明細!$A:$A,2026,差異明細!$B:$B,"YEARLY RUN-AIT350",差異明細!$C:$C,"2026-Q4")/10000 -> 0 | G16: =SUMIFS(差異明細!$E:$E,差異明細!$A:$A,2026,差異明細!$B:$B,"YEARLY RUN-AIT350",差異明細!$C:$C,2026)/10000 -> 2.13706 | H16: =SUMIFS(差異明細!$K:$K,差異明細!$A:$A,2026,差異明細!$B:$B,"YEARLY RUN-AIT350",差異明細!$C:$C,2026) -> 0
A17: YEARLY RUN-POLO | B17: =SUMIFS(差異明細!$G:$G,差異明細!$A:$A,2026,差異明細!$B:$B,"YEARLY RUN-POLO",差異明細!$C:$C,2026)/10000 -> 0 | C17: =SUMIFS(差異明細!$G:$G,差異明細!$A:$A,2026,差異明細!$B:$B,"YEARLY RUN-POLO",差異明細!$C:$C,"2026-Q1")/10000 -> 0 | D17: =SUMIFS(差異明細!$G:$G,差異明細!$A:$A,2026,差異明細!$B:$B,"YEARLY RUN-POLO",差異明細!$C:$C,"2026-Q2")/10000 -> 0 | E17: =SUMIFS(差異明細!$G:$G,差異明細!$A:$A,2026,差異明細!$B:$B,"YEARLY RUN-POLO",差異明細!$C:$C,"2026-Q3")/10000 -> 0 | F17: =SUMIFS(差異明細!$G:$G,差異明細!$A:$A,2026,差異明細!$B:$B,"YEARLY RUN-POLO",差異明細!$C:$C,"2026-Q4")/10000 -> 0 | G17: =SUMIFS(差異明細!$E:$E,差異明細!$A:$A,2026,差異明細!$B:$B,"YEARLY RUN-POLO",差異明細!$C:$C,2026)/10000 -> 16.26939 | H17: =SUMIFS(差異明細!$K:$K,差異明細!$A:$A,2026,差異明細!$B:$B,"YEARLY RUN-POLO",差異明細!$C:$C,2026) -> 0
A19: 三、2027 雙週差（標打，單位：萬）
A20: Program | B20: 2027 | C20: 2027-Q1 | D20: 2027-Q2 | E20: 2027-Q3 | F20: 2027-Q4 | G20: 本週全年(萬) | H20: NCMT差異
A21: 總計 | B21: =SUMIFS(差異明細!$G:$G,差異明細!$A:$A,2027,差異明細!$B:$B,"All Program",差異明細!$C:$C,2027)/10000 -> 0 | C21: =SUMIFS(差異明細!$G:$G,差異明細!$A:$A,2027,差異明細!$B:$B,"All Program",差異明細!$C:$C,"2027-Q1")/10000 -> 0 | D21: =SUMIFS(差異明細!$G:$G,差異明細!$A:$A,2027,差異明細!$B:$B,"All Program",差異明細!$C:$C,"2027-Q2")/10000 -> 0 | E21: =SUMIFS(差異明細!$G:$G,差異明細!$A:$A,2027,差異明細!$B:$B,"All Program",差異明細!$C:$C,"2027-Q3")/10000 -> 0 | F21: =SUMIFS(差異明細!$G:$G,差異明細!$A:$A,2027,差異明細!$B:$B,"All Program",差異明細!$C:$C,"2027-Q4")/10000 -> 0 | G21: =SUMIFS(差異明細!$E:$E,差異明細!$A:$A,2027,差異明細!$B:$B,"All Program",差異明細!$C:$C,2027)/10000 -> 88.41019 | H21: =SUMIFS(差異明細!$K:$K,差異明細!$A:$A,2027,差異明細!$B:$B,"All Program",差異明細!$C:$C,2027) -> 0
A22: SEASONAL | B22: =SUMIFS(差異明細!$G:$G,差異明細!$A:$A,2027,差異明細!$B:$B,"SEASONAL",差異明細!$C:$C,2027)/10000 -> 0 | C22: =SUMIFS(差異明細!$G:$G,差異明細!$A:$A,2027,差異明細!$B:$B,"SEASONAL",差異明細!$C:$C,"2027-Q1")/10000 -> 0 | D22: =SUMIFS(差異明細!$G:$G,差異明細!$A:$A,2027,差異明細!$B:$B,"SEASONAL",差異明細!$C:$C,"2027-Q2")/10000 -> 0 | E22: =SUMIFS(差異明細!$G:$G,差異明細!$A:$A,2027,差異明細!$B:$B,"SEASONAL",差異明細!$C:$C,"2027-Q3")/10000 -> 0 | F22: =SUMIFS(差異明細!$G:$G,差異明細!$A:$A,2027,差異明細!$B:$B,"SEASONAL",差異明細!$C:$C,"2027-Q4")/10000 -> 0 | G22: =SUMIFS(差異明細!$E:$E,差異明細!$A:$A,2027,差異明細!$B:$B,"SEASONAL",差異明細!$C:$C,2027)/10000 -> 6.77931 | H22: =SUMIFS(差異明細!$K:$K,差異明細!$A:$A,2027,差異明細!$B:$B,"SEASONAL",差異明細!$C:$C,2027) -> 0
A23: SEASONAL-SWEATER | B23: =SUMIFS(差異明細!$G:$G,差異明細!$A:$A,2027,差異明細!$B:$B,"SEASONAL-SWEATER",差異明細!$C:$C,2027)/10000 -> 0 | C23: =SUMIFS(差異明細!$G:$G,差異明細!$A:$A,2027,差異明細!$B:$B,"SEASONAL-SWEATER",差異明細!$C:$C,"2027-Q1")/10000 -> 0 | D23: =SUMIFS(差異明細!$G:$G,差異明細!$A:$A,2027,差異明細!$B:$B,"SEASONAL-SWEATER",差異明細!$C:$C,"2027-Q2")/10000 -> 0 | E23: =SUMIFS(差異明細!$G:$G,差異明細!$A:$A,2027,差異明細!$B:$B,"SEASONAL-SWEATER",差異明細!$C:$C,"2027-Q3")/10000 -> 0 | F23: =SUMIFS(差異明細!$G:$G,差異明細!$A:$A,2027,差異明細!$B:$B,"SEASONAL-SWEATER",差異明細!$C:$C,"2027-Q4")/10000 -> 0 | G23: =SUMIFS(差異明細!$E:$E,差異明細!$A:$A,2027,差異明細!$B:$B,"SEASONAL-SWEATER",差異明細!$C:$C,2027)/10000 -> 8.34536 | H23: =SUMIFS(差異明細!$K:$K,差異明細!$A:$A,2027,差異明細!$B:$B,"SEASONAL-SWEATER",差異明細!$C:$C,2027) -> 0
A24: YEARLY RUN-304ALT | B24: =SUMIFS(差異明細!$G:$G,差異明細!$A:$A,2027,差異明細!$B:$B,"YEARLY RUN-304ALT",差異明細!$C:$C,2027)/10000 -> 0 | C24: =SUMIFS(差異明細!$G:$G,差異明細!$A:$A,2027,差異明細!$B:$B,"YEARLY RUN-304ALT",差異明細!$C:$C,"2027-Q1")/10000 -> 0 | D24: =SUMIFS(差異明細!$G:$G,差異明細!$A:$A,2027,差異明細!$B:$B,"YEARLY RUN-304ALT",差異明細!$C:$C,"2027-Q2")/10000 -> 0 | E24: =SUMIFS(差異明細!$G:$G,差異明細!$A:$A,2027,差異明細!$B:$B,"YEARLY RUN-304ALT",差異明細!$C:$C,"2027-Q3")/10000 -> 0 | F24: =SUMIFS(差異明細!$G:$G,差異明細!$A:$A,2027,差異明細!$B:$B,"YEARLY RUN-304ALT",差異明細!$C:$C,"2027-Q4")/10000 -> 0 | G24: =SUMIFS(差異明細!$E:$E,差異明細!$A:$A,2027,差異明細!$B:$B,"YEARLY RUN-304ALT",差異明細!$C:$C,2027)/10000 -> 4.715 | H24: =SUMIFS(差異明細!$K:$K,差異明細!$A:$A,2027,差異明細!$B:$B,"YEARLY RUN-304ALT",差異明細!$C:$C,2027) -> 0
A25: YEARLY RUN-ACT300 | B25: =SUMIFS(差異明細!$G:$G,差異明細!$A:$A,2027,差異明細!$B:$B,"YEARLY RUN-ACT300",差異明細!$C:$C,2027)/10000 -> 0 | C25: =SUMIFS(差異明細!$G:$G,差異明細!$A:$A,2027,差異明細!$B:$B,"YEARLY RUN-ACT300",差異明細!$C:$C,"2027-Q1")/10000 -> 0 | D25: =SUMIFS(差異明細!$G:$G,差異明細!$A:$A,2027,差異明細!$B:$B,"YEARLY RUN-ACT300",差異明細!$C:$C,"2027-Q2")/10000 -> 0 | E25: =SUMIFS(差異明細!$G:$G,差異明細!$A:$A,2027,差異明細!$B:$B,"YEARLY RUN-ACT300",差異明細!$C:$C,"2027-Q3")/10000 -> 0 | F25: =SUMIFS(差異明細!$G:$G,差異明細!$A:$A,2027,差異明細!$B:$B,"YEARLY RUN-ACT300",差異明細!$C:$C,"2027-Q4")/10000 -> 0 | G25: =SUMIFS(差異明細!$E:$E,差異明細!$A:$A,2027,差異明細!$B:$B,"YEARLY RUN-ACT300",差異明細!$C:$C,2027)/10000 -> 48.10196 | H25: =SUMIFS(差異明細!$K:$K,差異明細!$A:$A,2027,差異明細!$B:$B,"YEARLY RUN-ACT300",差異明細!$C:$C,2027) -> 0
A26: YEARLY RUN-AIT350 | B26: =SUMIFS(差異明細!$G:$G,差異明細!$A:$A,2027,差異明細!$B:$B,"YEARLY RUN-AIT350",差異明細!$C:$C,2027)/10000 -> 0 | C26: =SUMIFS(差異明細!$G:$G,差異明細!$A:$A,2027,差異明細!$B:$B,"YEARLY RUN-AIT350",差異明細!$C:$C,"2027-Q1")/10000 -> 0 | D26: =SUMIFS(差異明細!$G:$G,差異明細!$A:$A,2027,差異明細!$B:$B,"YEARLY RUN-AIT350",差異明細!$C:$C,"2027-Q2")/10000 -> 0 | E26: =SUMIFS(差異明細!$G:$G,差異明細!$A:$A,2027,差異明細!$B:$B,"YEARLY RUN-AIT350",差異明細!$C:$C,"2027-Q3")/10000 -> 0 | F26: =SUMIFS(差異明細!$G:$G,差異明細!$A:$A,2027,差異明細!$B:$B,"YEARLY RUN-AIT350",差異明細!$C:$C,"2027-Q4")/10000 -> 0 | G26: =SUMIFS(差異明細!$E:$E,差異明細!$A:$A,2027,差異明細!$B:$B,"YEARLY RUN-AIT350",差異明細!$C:$C,2027)/10000 -> 1.46402 | H26: =SUMIFS(差異明細!$K:$K,差異明細!$A:$A,2027,差異明細!$B:$B,"YEARLY RUN-AIT350",差異明細!$C:$C,2027) -> 0
A27: YEARLY RUN-POLO | B27: =SUMIFS(差異明細!$G:$G,差異明細!$A:$A,2027,差異明細!$B:$B,"YEARLY RUN-POLO",差異明細!$C:$C,2027)/10000 -> 0 | C27: =SUMIFS(差異明細!$G:$G,差異明細!$A:$A,2027,差異明細!$B:$B,"YEARLY RUN-POLO",差異明細!$C:$C,"2027-Q1")/10000 -> 0 | D27: =SUMIFS(差異明細!$G:$G,差異明細!$A:$A,2027,差異明細!$B:$B,"YEARLY RUN-POLO",差異明細!$C:$C,"2027-Q2")/10000 -> 0 | E27: =SUMIFS(差異明細!$G:$G,差異明細!$A:$A,2027,差異明細!$B:$B,"YEARLY RUN-POLO",差異明細!$C:$C,"2027-Q3")/10000 -> 0 | F27: =SUMIFS(差異明細!$G:$G,差異明細!$A:$A,2027,差異明細!$B:$B,"YEARLY RUN-POLO",差異明細!$C:$C,"2027-Q4")/10000 -> 0 | G27: =SUMIFS(差異明細!$E:$E,差異明細!$A:$A,2027,差異明細!$B:$B,"YEARLY RUN-POLO",差異明細!$C:$C,2027)/10000 -> 19.00454 | H27: =SUMIFS(差異明細!$K:$K,差異明細!$A:$A,2027,差異明細!$B:$B,"YEARLY RUN-POLO",差異明細!$C:$C,2027) -> 0
A29: 四、差異說明（超過門檻的項目）
A30: Program | B30: 年度 | C30: 期間 | D30: 差異標打 | E30: 差異NCMT | F30: 原因 | G30: 說明
A31: =IFERROR(INDEX(差異明細!$B:$B,MATCH(1,差異明細!$M:$M,0)),"") | B31: =IFERROR(INDEX(差異明細!$A:$A,MATCH(1,差異明細!$M:$M,0))&"","") | C31: =IFERROR(INDEX(差異明細!$D:$D,MATCH(1,差異明細!$M:$M,0)),"") | D31: =IFERROR(INDEX(差異明細!$G:$G,MATCH(1,差異明細!$M:$M,0)),"") | E31: =IFERROR(INDEX(差異明細!$K:$K,MATCH(1,差異明細!$M:$M,0)),"") | F31: =IFERROR(IF(INDEX(差異明細!$N:$N,MATCH(1,差異明細!$M:$M,0))="","（待填）",INDEX(差異明細!$N:$N,MATCH(1,差異明細!$M:$M,0))),"") | G31: =IFERROR(INDEX(差異明細!$O:$O,MATCH(1,差異明細!$M:$M,0))&"","")
A32: =IFERROR(INDEX(差異明細!$B:$B,MATCH(2,差異明細!$M:$M,0)),"") | B32: =IFERROR(INDEX(差異明細!$A:$A,MATCH(2,差異明細!$M:$M,0))&"","") | C32: =IFERROR(INDEX(差異明細!$D:$D,MATCH(2,差異明細!$M:$M,0)),"") | D32: =IFERROR(INDEX(差異明細!$G:$G,MATCH(2,差異明細!$M:$M,0)),"") | E32: =IFERROR(INDEX(差異明細!$K:$K,MATCH(2,差異明細!$M:$M,0)),"") | F32: =IFERROR(IF(INDEX(差異明細!$N:$N,MATCH(2,差異明細!$M:$M,0))="","（待填）",INDEX(差異明細!$N:$N,MATCH(2,差異明細!$M:$M,0))),"") | G32: =IFERROR(INDEX(差異明細!$O:$O,MATCH(2,差異明細!$M:$M,0))&"","")
A33: =IFERROR(INDEX(差異明細!$B:$B,MATCH(3,差異明細!$M:$M,0)),"") | B33: =IFERROR(INDEX(差異明細!$A:$A,MATCH(3,差異明細!$M:$M,0))&"","") | C33: =IFERROR(INDEX(差異明細!$D:$D,MATCH(3,差異明細!$M:$M,0)),"") | D33: =IFERROR(INDEX(差異明細!$G:$G,MATCH(3,差異明細!$M:$M,0)),"") | E33: =IFERROR(INDEX(差異明細!$K:$K,MATCH(3,差異明細!$M:$M,0)),"") | F33: =IFERROR(IF(INDEX(差異明細!$N:$N,MATCH(3,差異明細!$M:$M,0))="","（待填）",INDEX(差異明細!$N:$N,MATCH(3,差異明細!$M:$M,0))),"") | G33: =IFERROR(INDEX(差異明細!$O:$O,MATCH(3,差異明細!$M:$M,0))&"","")
A34: =IFERROR(INDEX(差異明細!$B:$B,MATCH(4,差異明細!$M:$M,0)),"") | B34: =IFERROR(INDEX(差異明細!$A:$A,MATCH(4,差異明細!$M:$M,0))&"","") | C34: =IFERROR(INDEX(差異明細!$D:$D,MATCH(4,差異明細!$M:$M,0)),"") | D34: =IFERROR(INDEX(差異明細!$G:$G,MATCH(4,差異明細!$M:$M,0)),"") | E34: =IFERROR(INDEX(差異明細!$K:$K,MATCH(4,差異明細!$M:$M,0)),"") | F34: =IFERROR(IF(INDEX(差異明細!$N:$N,MATCH(4,差異明細!$M:$M,0))="","（待填）",INDEX(差異明細!$N:$N,MATCH(4,差異明細!$M:$M,0))),"") | G34: =IFERROR(INDEX(差異明細!$O:$O,MATCH(4,差異明細!$M:$M,0))&"","")
A35: =IFERROR(INDEX(差異明細!$B:$B,MATCH(5,差異明細!$M:$M,0)),"") | B35: =IFERROR(INDEX(差異明細!$A:$A,MATCH(5,差異明細!$M:$M,0))&"","") | C35: =IFERROR(INDEX(差異明細!$D:$D,MATCH(5,差異明細!$M:$M,0)),"") | D35: =IFERROR(INDEX(差異明細!$G:$G,MATCH(5,差異明細!$M:$M,0)),"") | E35: =IFERROR(INDEX(差異明細!$K:$K,MATCH(5,差異明細!$M:$M,0)),"") | F35: =IFERROR(IF(INDEX(差異明細!$N:$N,MATCH(5,差異明細!$M:$M,0))="","（待填）",INDEX(差異明細!$N:$N,MATCH(5,差異明細!$M:$M,0))),"") | G35: =IFERROR(INDEX(差異明細!$O:$O,MATCH(5,差異明細!$M:$M,0))&"","")
A36: =IFERROR(INDEX(差異明細!$B:$B,MATCH(6,差異明細!$M:$M,0)),"") | B36: =IFERROR(INDEX(差異明細!$A:$A,MATCH(6,差異明細!$M:$M,0))&"","") | C36: =IFERROR(INDEX(差異明細!$D:$D,MATCH(6,差異明細!$M:$M,0)),"") | D36: =IFERROR(INDEX(差異明細!$G:$G,MATCH(6,差異明細!$M:$M,0)),"") | E36: =IFERROR(INDEX(差異明細!$K:$K,MATCH(6,差異明細!$M:$M,0)),"") | F36: =IFERROR(IF(INDEX(差異明細!$N:$N,MATCH(6,差異明細!$M:$M,0))="","（待填）",INDEX(差異明細!$N:$N,MATCH(6,差異明細!$M:$M,0))),"") | G36: =IFERROR(INDEX(差異明細!$O:$O,MATCH(6,差異明細!$M:$M,0))&"","")
A37: =IFERROR(INDEX(差異明細!$B:$B,MATCH(7,差異明細!$M:$M,0)),"") | B37: =IFERROR(INDEX(差異明細!$A:$A,MATCH(7,差異明細!$M:$M,0))&"","") | C37: =IFERROR(INDEX(差異明細!$D:$D,MATCH(7,差異明細!$M:$M,0)),"") | D37: =IFERROR(INDEX(差異明細!$G:$G,MATCH(7,差異明細!$M:$M,0)),"") | E37: =IFERROR(INDEX(差異明細!$K:$K,MATCH(7,差異明細!$M:$M,0)),"") | F37: =IFERROR(IF(INDEX(差異明細!$N:$N,MATCH(7,差異明細!$M:$M,0))="","（待填）",INDEX(差異明細!$N:$N,MATCH(7,差異明細!$M:$M,0))),"") | G37: =IFERROR(INDEX(差異明細!$O:$O,MATCH(7,差異明細!$M:$M,0))&"","")
A38: =IFERROR(INDEX(差異明細!$B:$B,MATCH(8,差異明細!$M:$M,0)),"") | B38: =IFERROR(INDEX(差異明細!$A:$A,MATCH(8,差異明細!$M:$M,0))&"","") | C38: =IFERROR(INDEX(差異明細!$D:$D,MATCH(8,差異明細!$M:$M,0)),"") | D38: =IFERROR(INDEX(差異明細!$G:$G,MATCH(8,差異明細!$M:$M,0)),"") | E38: =IFERROR(INDEX(差異明細!$K:$K,MATCH(8,差異明細!$M:$M,0)),"") | F38: =IFERROR(IF(INDEX(差異明細!$N:$N,MATCH(8,差異明細!$M:$M,0))="","（待填）",INDEX(差異明細!$N:$N,MATCH(8,差異明細!$M:$M,0))),"") | G38: =IFERROR(INDEX(差異明細!$O:$O,MATCH(8,差異明細!$M:$M,0))&"","")
A39: =IFERROR(INDEX(差異明細!$B:$B,MATCH(9,差異明細!$M:$M,0)),"") | B39: =IFERROR(INDEX(差異明細!$A:$A,MATCH(9,差異明細!$M:$M,0))&"","") | C39: =IFERROR(INDEX(差異明細!$D:$D,MATCH(9,差異明細!$M:$M,0)),"") | D39: =IFERROR(INDEX(差異明細!$G:$G,MATCH(9,差異明細!$M:$M,0)),"") | E39: =IFERROR(INDEX(差異明細!$K:$K,MATCH(9,差異明細!$M:$M,0)),"") | F39: =IFERROR(IF(INDEX(差異明細!$N:$N,MATCH(9,差異明細!$M:$M,0))="","（待填）",INDEX(差異明細!$N:$N,MATCH(9,差異明細!$M:$M,0))),"") | G39: =IFERROR(INDEX(差異明細!$O:$O,MATCH(9,差異明細!$M:$M,0))&"","")
A40: =IFERROR(INDEX(差異明細!$B:$B,MATCH(10,差異明細!$M:$M,0)),"") | B40: =IFERROR(INDEX(差異明細!$A:$A,MATCH(10,差異明細!$M:$M,0))&"","") | C40: =IFERROR(INDEX(差異明細!$D:$D,MATCH(10,差異明細!$M:$M,0)),"") | D40: =IFERROR(INDEX(差異明細!$G:$G,MATCH(10,差異明細!$M:$M,0)),"") | E40: =IFERROR(INDEX(差異明細!$K:$K,MATCH(10,差異明細!$M:$M,0)),"") | F40: =IFERROR(IF(INDEX(差異明細!$N:$N,MATCH(10,差異明細!$M:$M,0))="","（待填）",INDEX(差異明細!$N:$N,MATCH(10,差異明細!$M:$M,0))),"") | G40: =IFERROR(INDEX(差異明細!$O:$O,MATCH(10,差異明細!$M:$M,0))&"","")
A41: =IFERROR(INDEX(差異明細!$B:$B,MATCH(11,差異明細!$M:$M,0)),"") | B41: =IFERROR(INDEX(差異明細!$A:$A,MATCH(11,差異明細!$M:$M,0))&"","") | C41: =IFERROR(INDEX(差異明細!$D:$D,MATCH(11,差異明細!$M:$M,0)),"") | D41: =IFERROR(INDEX(差異明細!$G:$G,MATCH(11,差異明細!$M:$M,0)),"") | E41: =IFERROR(INDEX(差異明細!$K:$K,MATCH(11,差異明細!$M:$M,0)),"") | F41: =IFERROR(IF(INDEX(差異明細!$N:$N,MATCH(11,差異明細!$M:$M,0))="","（待填）",INDEX(差異明細!$N:$N,MATCH(11,差異明細!$M:$M,0))),"") | G41: =IFERROR(INDEX(差異明細!$O:$O,MATCH(11,差異明細!$M:$M,0))&"","")
A42: =IFERROR(INDEX(差異明細!$B:$B,MATCH(12,差異明細!$M:$M,0)),"") | B42: =IFERROR(INDEX(差異明細!$A:$A,MATCH(12,差異明細!$M:$M,0))&"","") | C42: =IFERROR(INDEX(差異明細!$D:$D,MATCH(12,差異明細!$M:$M,0)),"") | D42: =IFERROR(INDEX(差異明細!$G:$G,MATCH(12,差異明細!$M:$M,0)),"") | E42: =IFERROR(INDEX(差異明細!$K:$K,MATCH(12,差異明細!$M:$M,0)),"") | F42: =IFERROR(IF(INDEX(差異明細!$N:$N,MATCH(12,差異明細!$M:$M,0))="","（待填）",INDEX(差異明細!$N:$N,MATCH(12,差異明細!$M:$M,0))),"") | G42: =IFERROR(INDEX(差異明細!$O:$O,MATCH(12,差異明細!$M:$M,0))&"","")
A43: =IFERROR(INDEX(差異明細!$B:$B,MATCH(13,差異明細!$M:$M,0)),"") | B43: =IFERROR(INDEX(差異明細!$A:$A,MATCH(13,差異明細!$M:$M,0))&"","") | C43: =IFERROR(INDEX(差異明細!$D:$D,MATCH(13,差異明細!$M:$M,0)),"") | D43: =IFERROR(INDEX(差異明細!$G:$G,MATCH(13,差異明細!$M:$M,0)),"") | E43: =IFERROR(INDEX(差異明細!$K:$K,MATCH(13,差異明細!$M:$M,0)),"") | F43: =IFERROR(IF(INDEX(差異明細!$N:$N,MATCH(13,差異明細!$M:$M,0))="","（待填）",INDEX(差異明細!$N:$N,MATCH(13,差異明細!$M:$M,0))),"") | G43: =IFERROR(INDEX(差異明細!$O:$O,MATCH(13,差異明細!$M:$M,0))&"","")
A44: =IFERROR(INDEX(差異明細!$B:$B,MATCH(14,差異明細!$M:$M,0)),"") | B44: =IFERROR(INDEX(差異明細!$A:$A,MATCH(14,差異明細!$M:$M,0))&"","") | C44: =IFERROR(INDEX(差異明細!$D:$D,MATCH(14,差異明細!$M:$M,0)),"") | D44: =IFERROR(INDEX(差異明細!$G:$G,MATCH(14,差異明細!$M:$M,0)),"") | E44: =IFERROR(INDEX(差異明細!$K:$K,MATCH(14,差異明細!$M:$M,0)),"") | F44: =IFERROR(IF(INDEX(差異明細!$N:$N,MATCH(14,差異明細!$M:$M,0))="","（待填）",INDEX(差異明細!$N:$N,MATCH(14,差異明細!$M:$M,0))),"") | G44: =IFERROR(INDEX(差異明細!$O:$O,MATCH(14,差異明細!$M:$M,0))&"","")
...

Sheet 差異明細
A1: 差異明細與說明
A2: ="本週 "&TEXT(說明!$C$5,"yyyy/mm/dd")&" vs 前期 "&TEXT(說明!$C$6,"yyyy/mm/dd")&" ｜ 門檻：標打 ±"&TEXT(說明!$C$7,"#,##0")&"、NCMT ±"&TEXT(說明!$C$8,"0.00") -> 本週 2026/10/07 vs 前期 2026/09/23 ｜ 門檻：標打 ±3,000、NCMT ±0.30
A4: 年度 | B4: Program | C4: 期間鍵 | D4: 期間 | E4: 本週標打 | F4: 前期標打 | G4: 差異標打 | H4: 差異% | I4: 本週NCMT | J4: 前期NCMT | K4: 差異NCMT | L4: 需說明 | M4: 序號 | N4: 原因 | O4: 說明 | P4: 確認人
A5: 2026 | B5: All Program | C5: 2026 | D5: 全年 | E5: =IFERROR(SUMIFS(INDEX(本週_2026!$D$2:$Z$300,0,MATCH($C5,本週_2026!$D$1:$Z$1,0)),本週_2026!$A$2:$A$300,"標打",本週_2026!$B$2:$B$300,"All Iscfm",本週_2026!$C$2:$C$300,$B5),0) -> 988688.2 | F5: =IFERROR(SUMIFS(INDEX(前期_2026!$D$2:$Z$300,0,MATCH($C5,前期_2026!$D$1:$Z$1,0)),前期_2026!$A$2:$A$300,"標打",前期_2026!$B$2:$B$300,"All Iscfm",前期_2026!$C$2:$C$300,$B5),0) -> 988688.2 | G5: =E5-F5 -> 0 | H5: =IF(F5=0,"",G5/F5) -> 0 | I5: =IFERROR(SUMIFS(INDEX(本週_2026!$D$2:$Z$300,0,MATCH($C5,本週_2026!$D$1:$Z$1,0)),本週_2026!$A$2:$A$300,"NET_CMT_標打_成改後",本週_2026!$B$2:$B$300,"All Iscfm",本週_2026!$C$2:$C$300,$B5),0) -> 19.16 | J5: =IFERROR(SUMIFS(INDEX(前期_2026!$D$2:$Z$300,0,MATCH($C5,前期_2026!$D$1:$Z$1,0)),前期_2026!$A$2:$A$300,"NET_CMT_標打_成改後",前期_2026!$B$2:$B$300,"All Iscfm",前期_2026!$C$2:$C$300,$B5),0) -> 19.16 | K5: =I5-J5 -> 0 | L5: =IF($B5="All Program","",IF(OR(ABS(G5)>=說明!$C$7,ABS(K5)>=說明!$C$8),"需說明","")) | M5: =IF(L5="需說明",COUNTIF($L$5:L5,"需說明"),"")
A6: 2026 | B6: All Program | C6: 2026-Q1 | D6: Q1 | E6: =IFERROR(SUMIFS(INDEX(本週_2026!$D$2:$Z$300,0,MATCH($C6,本週_2026!$D$1:$Z$1,0)),本週_2026!$A$2:$A$300,"標打",本週_2026!$B$2:$B$300,"All Iscfm",本週_2026!$C$2:$C$300,$B6),0) -> 206294.1 | F6: =IFERROR(SUMIFS(INDEX(前期_2026!$D$2:$Z$300,0,MATCH($C6,前期_2026!$D$1:$Z$1,0)),前期_2026!$A$2:$A$300,"標打",前期_2026!$B$2:$B$300,"All Iscfm",前期_2026!$C$2:$C$300,$B6),0) -> 206294.1 | G6: =E6-F6 -> 0 | H6: =IF(F6=0,"",G6/F6) -> 0 | I6: =IFERROR(SUMIFS(INDEX(本週_2026!$D$2:$Z$300,0,MATCH($C6,本週_2026!$D$1:$Z$1,0)),本週_2026!$A$2:$A$300,"NET_CMT_標打_成改後",本週_2026!$B$2:$B$300,"All Iscfm",本週_2026!$C$2:$C$300,$B6),0) -> 20.33 | J6: =IFERROR(SUMIFS(INDEX(前期_2026!$D$2:$Z$300,0,MATCH($C6,前期_2026!$D$1:$Z$1,0)),前期_2026!$A$2:$A$300,"NET_CMT_標打_成改後",前期_2026!$B$2:$B$300,"All Iscfm",前期_2026!$C$2:$C$300,$B6),0) -> 20.33 | K6: =I6-J6 -> 0 | L6: =IF($B6="All Program","",IF(OR(ABS(G6)>=說明!$C$7,ABS(K6)>=說明!$C$8),"需說明","")) | M6: =IF(L6="需說明",COUNTIF($L$5:L6,"需說明"),"")
A7: 2026 | B7: All Program | C7: 2026-Q2 | D7: Q2 | E7: =IFERROR(SUMIFS(INDEX(本週_2026!$D$2:$Z$300,0,MATCH($C7,本週_2026!$D$1:$Z$1,0)),本週_2026!$A$2:$A$300,"標打",本週_2026!$B$2:$B$300,"All Iscfm",本週_2026!$C$2:$C$300,$B7),0) -> 243675.4 | F7: =IFERROR(SUMIFS(INDEX(前期_2026!$D$2:$Z$300,0,MATCH($C7,前期_2026!$D$1:$Z$1,0)),前期_2026!$A$2:$A$300,"標打",前期_2026!$B$2:$B$300,"All Iscfm",前期_2026!$C$2:$C$300,$B7),0) -> 243675.4 | G7: =E7-F7 -> 0 | H7: =IF(F7=0,"",G7/F7) -> 0 | I7: =IFERROR(SUMIFS(INDEX(本週_2026!$D$2:$Z$300,0,MATCH($C7,本週_2026!$D$1:$Z$1,0)),本週_2026!$A$2:$A$300,"NET_CMT_標打_成改後",本週_2026!$B$2:$B$300,"All Iscfm",本週_2026!$C$2:$C$300,$B7),0) -> 19.57 | J7: =IFERROR(SUMIFS(INDEX(前期_2026!$D$2:$Z$300,0,MATCH($C7,前期_2026!$D$1:$Z$1,0)),前期_2026!$A$2:$A$300,"NET_CMT_標打_成改後",前期_2026!$B$2:$B$300,"All Iscfm",前期_2026!$C$2:$C$300,$B7),0) -> 19.57 | K7: =I7-J7 -> 0 | L7: =IF($B7="All Program","",IF(OR(ABS(G7)>=說明!$C$7,ABS(K7)>=說明!$C$8),"需說明","")) | M7: =IF(L7="需說明",COUNTIF($L$5:L7,"需說明"),"")
A8: 2026 | B8: All Program | C8: 2026-Q3 | D8: Q3 | E8: =IFERROR(SUMIFS(INDEX(本週_2026!$D$2:$Z$300,0,MATCH($C8,本週_2026!$D$1:$Z$1,0)),本週_2026!$A$2:$A$300,"標打",本週_2026!$B$2:$B$300,"All Iscfm",本週_2026!$C$2:$C$300,$B8),0) -> 288629.2 | F8: =IFERROR(SUMIFS(INDEX(前期_2026!$D$2:$Z$300,0,MATCH($C8,前期_2026!$D$1:$Z$1,0)),前期_2026!$A$2:$A$300,"標打",前期_2026!$B$2:$B$300,"All Iscfm",前期_2026!$C$2:$C$300,$B8),0) -> 288629.2 | G8: =E8-F8 -> 0 | H8: =IF(F8=0,"",G8/F8) -> 0 | I8: =IFERROR(SUMIFS(INDEX(本週_2026!$D$2:$Z$300,0,MATCH($C8,本週_2026!$D$1:$Z$1,0)),本週_2026!$A$2:$A$300,"NET_CMT_標打_成改後",本週_2026!$B$2:$B$300,"All Iscfm",本週_2026!$C$2:$C$300,$B8),0) -> 18.32 | J8: =IFERROR(SUMIFS(INDEX(前期_2026!$D$2:$Z$300,0,MATCH($C8,前期_2026!$D$1:$Z$1,0)),前期_2026!$A$2:$A$300,"NET_CMT_標打_成改後",前期_2026!$B$2:$B$300,"All Iscfm",前期_2026!$C$2:$C$300,$B8),0) -> 18.32 | K8: =I8-J8 -> 0 | L8: =IF($B8="All Program","",IF(OR(ABS(G8)>=說明!$C$7,ABS(K8)>=說明!$C$8),"需說明","")) | M8: =IF(L8="需說明",COUNTIF($L$5:L8,"需說明"),"")
A9: 2026 | B9: All Program | C9: 2026-Q4 | D9: Q4 | E9: =IFERROR(SUMIFS(INDEX(本週_2026!$D$2:$Z$300,0,MATCH($C9,本週_2026!$D$1:$Z$1,0)),本週_2026!$A$2:$A$300,"標打",本週_2026!$B$2:$B$300,"All Iscfm",本週_2026!$C$2:$C$300,$B9),0) -> 250089.5 | F9: =IFERROR(SUMIFS(INDEX(前期_2026!$D$2:$Z$300,0,MATCH($C9,前期_2026!$D$1:$Z$1,0)),前期_2026!$A$2:$A$300,"標打",前期_2026!$B$2:$B$300,"All Iscfm",前期_2026!$C$2:$C$300,$B9),0) -> 250089.5 | G9: =E9-F9 -> 0 | H9: =IF(F9=0,"",G9/F9) -> 0 | I9: =IFERROR(SUMIFS(INDEX(本週_2026!$D$2:$Z$300,0,MATCH($C9,本週_2026!$D$1:$Z$1,0)),本週_2026!$A$2:$A$300,"NET_CMT_標打_成改後",本週_2026!$B$2:$B$300,"All Iscfm",本週_2026!$C$2:$C$300,$B9),0) -> 18.77 | J9: =IFERROR(SUMIFS(INDEX(前期_2026!$D$2:$Z$300,0,MATCH($C9,前期_2026!$D$1:$Z$1,0)),前期_2026!$A$2:$A$300,"NET_CMT_標打_成改後",前期_2026!$B$2:$B$300,"All Iscfm",前期_2026!$C$2:$C$300,$B9),0) -> 18.77 | K9: =I9-J9 -> 0 | L9: =IF($B9="All Program","",IF(OR(ABS(G9)>=說明!$C$7,ABS(K9)>=說明!$C$8),"需說明","")) | M9: =IF(L9="需說明",COUNTIF($L$5:L9,"需說明"),"")
A10: 2026 | B10: SEASONAL | C10: 2026 | D10: 全年 | E10: =IFERROR(SUMIFS(INDEX(本週_2026!$D$2:$Z$300,0,MATCH($C10,本週_2026!$D$1:$Z$1,0)),本週_2026!$A$2:$A$300,"標打",本週_2026!$B$2:$B$300,"All Iscfm",本週_2026!$C$2:$C$300,$B10),0) -> 66847.8 | F10: =IFERROR(SUMIFS(INDEX(前期_2026!$D$2:$Z$300,0,MATCH($C10,前期_2026!$D$1:$Z$1,0)),前期_2026!$A$2:$A$300,"標打",前期_2026!$B$2:$B$300,"All Iscfm",前期_2026!$C$2:$C$300,$B10),0) -> 66847.8 | G10: =E10-F10 -> 0 | H10: =IF(F10=0,"",G10/F10) -> 0 | I10: =IFERROR(SUMIFS(INDEX(本週_2026!$D$2:$Z$300,0,MATCH($C10,本週_2026!$D$1:$Z$1,0)),本週_2026!$A$2:$A$300,"NET_CMT_標打_成改後",本週_2026!$B$2:$B$300,"All Iscfm",本週_2026!$C$2:$C$300,$B10),0) -> 20.09 | J10: =IFERROR(SUMIFS(INDEX(前期_2026!$D$2:$Z$300,0,MATCH($C10,前期_2026!$D$1:$Z$1,0)),前期_2026!$A$2:$A$300,"NET_CMT_標打_成改後",前期_2026!$B$2:$B$300,"All Iscfm",前期_2026!$C$2:$C$300,$B10),0) -> 20.09 | K10: =I10-J10 -> 0 | L10: =IF($B10="All Program","",IF(OR(ABS(G10)>=說明!$C$7,ABS(K10)>=說明!$C$8),"需說明","")) | M10: =IF(L10="需說明",COUNTIF($L$5:L10,"需說明"),"")
A11: 2026 | B11: SEASONAL | C11: 2026-Q1 | D11: Q1 | E11: =IFERROR(SUMIFS(INDEX(本週_2026!$D$2:$Z$300,0,MATCH($C11,本週_2026!$D$1:$Z$1,0)),本週_2026!$A$2:$A$300,"標打",本週_2026!$B$2:$B$300,"All Iscfm",本週_2026!$C$2:$C$300,$B11),0) -> 9432.4 | F11: =IFERROR(SUMIFS(INDEX(前期_2026!$D$2:$Z$300,0,MATCH($C11,前期_2026!$D$1:$Z$1,0)),前期_2026!$A$2:$A$300,"標打",前期_2026!$B$2:$B$300,"All Iscfm",前期_2026!$C$2:$C$300,$B11),0) -> 9432.4 | G11: =E11-F11 -> 0 | H11: =IF(F11=0,"",G11/F11) -> 0 | I11: =IFERROR(SUMIFS(INDEX(本週_2026!$D$2:$Z$300,0,MATCH($C11,本週_2026!$D$1:$Z$1,0)),本週_2026!$A$2:$A$300,"NET_CMT_標打_成改後",本週_2026!$B$2:$B$300,"All Iscfm",本週_2026!$C$2:$C$300,$B11),0) -> 20.54 | J11: =IFERROR(SUMIFS(INDEX(前期_2026!$D$2:$Z$300,0,MATCH($C11,前期_2026!$D$1:$Z$1,0)),前期_2026!$A$2:$A$300,"NET_CMT_標打_成改後",前期_2026!$B$2:$B$300,"All Iscfm",前期_2026!$C$2:$C$300,$B11),0) -> 20.54 | K11: =I11-J11 -> 0 | L11: =IF($B11="All Program","",IF(OR(ABS(G11)>=說明!$C$7,ABS(K11)>=說明!$C$8),"需說明","")) | M11: =IF(L11="需說明",COUNTIF($L$5:L11,"需說明"),"")
A12: 2026 | B12: SEASONAL | C12: 2026-Q2 | D12: Q2 | E12: =IFERROR(SUMIFS(INDEX(本週_2026!$D$2:$Z$300,0,MATCH($C12,本週_2026!$D$1:$Z$1,0)),本週_2026!$A$2:$A$300,"標打",本週_2026!$B$2:$B$300,"All Iscfm",本週_2026!$C$2:$C$300,$B12),0) -> 21764.2 | F12: =IFERROR(SUMIFS(INDEX(前期_2026!$D$2:$Z$300,0,MATCH($C12,前期_2026!$D$1:$Z$1,0)),前期_2026!$A$2:$A$300,"標打",前期_2026!$B$2:$B$300,"All Iscfm",前期_2026!$C$2:$C$300,$B12),0) -> 21764.2 | G12: =E12-F12 -> 0 | H12: =IF(F12=0,"",G12/F12) -> 0 | I12: =IFERROR(SUMIFS(INDEX(本週_2026!$D$2:$Z$300,0,MATCH($C12,本週_2026!$D$1:$Z$1,0)),本週_2026!$A$2:$A$300,"NET_CMT_標打_成改後",本週_2026!$B$2:$B$300,"All Iscfm",本週_2026!$C$2:$C$300,$B12),0) -> 21.05 | J12: =IFERROR(SUMIFS(INDEX(前期_2026!$D$2:$Z$300,0,MATCH($C12,前期_2026!$D$1:$Z$1,0)),前期_2026!$A$2:$A$300,"NET_CMT_標打_成改後",前期_2026!$B$2:$B$300,"All Iscfm",前期_2026!$C$2:$C$300,$B12),0) -> 21.05 | K12: =I12-J12 -> 0 | L12: =IF($B12="All Program","",IF(OR(ABS(G12)>=說明!$C$7,ABS(K12)>=說明!$C$8),"需說明","")) | M12: =IF(L12="需說明",COUNTIF($L$5:L12,"需說明"),"")
A13: 2026 | B13: SEASONAL | C13: 2026-Q3 | D13: Q3 | E13: =IFERROR(SUMIFS(INDEX(本週_2026!$D$2:$Z$300,0,MATCH($C13,本週_2026!$D$1:$Z$1,0)),本週_2026!$A$2:$A$300,"標打",本週_2026!$B$2:$B$300,"All Iscfm",本週_2026!$C$2:$C$300,$B13),0) -> 17685.8 | F13: =IFERROR(SUMIFS(INDEX(前期_2026!$D$2:$Z$300,0,MATCH($C13,前期_2026!$D$1:$Z$1,0)),前期_2026!$A$2:$A$300,"標打",前期_2026!$B$2:$B$300,"All Iscfm",前期_2026!$C$2:$C$300,$B13),0) -> 17685.8 | G13: =E13-F13 -> 0 | H13: =IF(F13=0,"",G13/F13) -> 0 | I13: =IFERROR(SUMIFS(INDEX(本週_2026!$D$2:$Z$300,0,MATCH($C13,本週_2026!$D$1:$Z$1,0)),本週_2026!$A$2:$A$300,"NET_CMT_標打_成改後",本週_2026!$B$2:$B$300,"All Iscfm",本週_2026!$C$2:$C$300,$B13),0) -> 19.11 | J13: =IFERROR(SUMIFS(INDEX(前期_2026!$D$2:$Z$300,0,MATCH($C13,前期_2026!$D$1:$Z$1,0)),前期_2026!$A$2:$A$300,"NET_CMT_標打_成改後",前期_2026!$B$2:$B$300,"All Iscfm",前期_2026!$C$2:$C$300,$B13),0) -> 19.11 | K13: =I13-J13 -> 0 | L13: =IF($B13="All Program","",IF(OR(ABS(G13)>=說明!$C$7,ABS(K13)>=說明!$C$8),"需說明","")) | M13: =IF(L13="需說明",COUNTIF($L$5:L13,"需說明"),"")
A14: 2026 | B14: SEASONAL | C14: 2026-Q4 | D14: Q4 | E14: =IFERROR(SUMIFS(INDEX(本週_2026!$D$2:$Z$300,0,MATCH($C14,本週_2026!$D$1:$Z$1,0)),本週_2026!$A$2:$A$300,"標打",本週_2026!$B$2:$B$300,"All Iscfm",本週_2026!$C$2:$C$300,$B14),0) -> 17965.3 | F14: =IFERROR(SUMIFS(INDEX(前期_2026!$D$2:$Z$300,0,MATCH($C14,前期_2026!$D$1:$Z$1,0)),前期_2026!$A$2:$A$300,"標打",前期_2026!$B$2:$B$300,"All Iscfm",前期_2026!$C$2:$C$300,$B14),0) -> 17965.3 | G14: =E14-F14 -> 0 | H14: =IF(F14=0,"",G14/F14) -> 0 | I14: =IFERROR(SUMIFS(INDEX(本週_2026!$D$2:$Z$300,0,MATCH($C14,本週_2026!$D$1:$Z$1,0)),本週_2026!$A$2:$A$300,"NET_CMT_標打_成改後",本週_2026!$B$2:$B$300,"All Iscfm",本週_2026!$C$2:$C$300,$B14),0) -> 19.66 | J14: =IFERROR(SUMIFS(INDEX(前期_2026!$D$2:$Z$300,0,MATCH($C14,前期_2026!$D$1:$Z$1,0)),前期_2026!$A$2:$A$300,"NET_CMT_標打_成改後",前期_2026!$B$2:$B$300,"All Iscfm",前期_2026!$C$2:$C$300,$B14),0) -> 19.66 | K14: =I14-J14 -> 0 | L14: =IF($B14="All Program","",IF(OR(ABS(G14)>=說明!$C$7,ABS(K14)>=說明!$C$8),"需說明","")) | M14: =IF(L14="需說明",COUNTIF($L$5:L14,"需說明"),"")
A15: 2026 | B15: SEASONAL-SWEATER | C15: 2026 | D15: 全年 | E15: =IFERROR(SUMIFS(INDEX(本週_2026!$D$2:$Z$300,0,MATCH($C15,本週_2026!$D$1:$Z$1,0)),本週_2026!$A$2:$A$300,"標打",本週_2026!$B$2:$B$300,"All Iscfm",本週_2026!$C$2:$C$300,$B15),0) -> 95393.1 | F15: =IFERROR(SUMIFS(INDEX(前期_2026!$D$2:$Z$300,0,MATCH($C15,前期_2026!$D$1:$Z$1,0)),前期_2026!$A$2:$A$300,"標打",前期_2026!$B$2:$B$300,"All Iscfm",前期_2026!$C$2:$C$300,$B15),0) -> 95393.1 | G15: =E15-F15 -> 0 | H15: =IF(F15=0,"",G15/F15) -> 0 | I15: =IFERROR(SUMIFS(INDEX(本週_2026!$D$2:$Z$300,0,MATCH($C15,本週_2026!$D$1:$Z$1,0)),本週_2026!$A$2:$A$300,"NET_CMT_標打_成改後",本週_2026!$B$2:$B$300,"All Iscfm",本週_2026!$C$2:$C$300,$B15),0) -> 17.93 | J15: =IFERROR(SUMIFS(INDEX(前期_2026!$D$2:$Z$300,0,MATCH($C15,前期_2026!$D$1:$Z$1,0)),前期_2026!$A$2:$A$300,"NET_CMT_標打_成改後",前期_2026!$B$2:$B$300,"All Iscfm",前期_2026!$C$2:$C$300,$B15),0) -> 17.93 | K15: =I15-J15 -> 0 | L15: =IF($B15="All Program","",IF(OR(ABS(G15)>=說明!$C$7,ABS(K15)>=說明!$C$8),"需說明","")) | M15: =IF(L15="需說明",COUNTIF($L$5:L15,"需說明"),"")
A16: 2026 | B16: SEASONAL-SWEATER | C16: 2026-Q1 | D16: Q1 | E16: =IFERROR(SUMIFS(INDEX(本週_2026!$D$2:$Z$300,0,MATCH($C16,本週_2026!$D$1:$Z$1,0)),本週_2026!$A$2:$A$300,"標打",本週_2026!$B$2:$B$300,"All Iscfm",本週_2026!$C$2:$C$300,$B16),0) -> 20595.7 | F16: =IFERROR(SUMIFS(INDEX(前期_2026!$D$2:$Z$300,0,MATCH($C16,前期_2026!$D$1:$Z$1,0)),前期_2026!$A$2:$A$300,"標打",前期_2026!$B$2:$B$300,"All Iscfm",前期_2026!$C$2:$C$300,$B16),0) -> 20595.7 | G16: =E16-F16 -> 0 | H16: =IF(F16=0,"",G16/F16) -> 0 | I16: =IFERROR(SUMIFS(INDEX(本週_2026!$D$2:$Z$300,0,MATCH($C16,本週_2026!$D$1:$Z$1,0)),本週_2026!$A$2:$A$300,"NET_CMT_標打_成改後",本週_2026!$B$2:$B$300,"All Iscfm",本週_2026!$C$2:$C$300,$B16),0) -> 18.64 | J16: =IFERROR(SUMIFS(INDEX(前期_2026!$D$2:$Z$300,0,MATCH($C16,前期_2026!$D$1:$Z$1,0)),前期_2026!$A$2:$A$300,"NET_CMT_標打_成改後",前期_2026!$B$2:$B$300,"All Iscfm",前期_2026!$C$2:$C$300,$B16),0) -> 18.64 | K16: =I16-J16 -> 0 | L16: =IF($B16="All Program","",IF(OR(ABS(G16)>=說明!$C$7,ABS(K16)>=說明!$C$8),"需說明","")) | M16: =IF(L16="需說明",COUNTIF($L$5:L16,"需說明"),"")
A17: 2026 | B17: SEASONAL-SWEATER | C17: 2026-Q2 | D17: Q2 | E17: =IFERROR(SUMIFS(INDEX(本週_2026!$D$2:$Z$300,0,MATCH($C17,本週_2026!$D$1:$Z$1,0)),本週_2026!$A$2:$A$300,"標打",本週_2026!$B$2:$B$300,"All Iscfm",本週_2026!$C$2:$C$300,$B17),0) -> 13833.8 | F17: =IFERROR(SUMIFS(INDEX(前期_2026!$D$2:$Z$300,0,MATCH($C17,前期_2026!$D$1:$Z$1,0)),前期_2026!$A$2:$A$300,"標打",前期_2026!$B$2:$B$300,"All Iscfm",前期_2026!$C$2:$C$300,$B17),0) -> 13833.8 | G17: =E17-F17 -> 0 | H17: =IF(F17=0,"",G17/F17) -> 0 | I17: =IFERROR(SUMIFS(INDEX(本週_2026!$D$2:$Z$300,0,MATCH($C17,本週_2026!$D$1:$Z$1,0)),本週_2026!$A$2:$A$300,"NET_CMT_標打_成改後",本週_2026!$B$2:$B$300,"All Iscfm",本週_2026!$C$2:$C$300,$B17),0) -> 17.89 | J17: =IFERROR(SUMIFS(INDEX(前期_2026!$D$2:$Z$300,0,MATCH($C17,前期_2026!$D$1:$Z$1,0)),前期_2026!$A$2:$A$300,"NET_CMT_標打_成改後",前期_2026!$B$2:$B$300,"All Iscfm",前期_2026!$C$2:$C$300,$B17),0) -> 17.89 | K17: =I17-J17 -> 0 | L17: =IF($B17="All Program","",IF(OR(ABS(G17)>=說明!$C$7,ABS(K17)>=說明!$C$8),"需說明","")) | M17: =IF(L17="需說明",COUNTIF($L$5:L17,"需說明"),"")
A18: 2026 | B18: SEASONAL-SWEATER | C18: 2026-Q3 | D18: Q3 | E18: =IFERROR(SUMIFS(INDEX(本週_2026!$D$2:$Z$300,0,MATCH($C18,本週_2026!$D$1:$Z$1,0)),本週_2026!$A$2:$A$300,"標打",本週_2026!$B$2:$B$300,"All Iscfm",本週_2026!$C$2:$C$300,$B18),0) -> 32195.7 | F18: =IFERROR(SUMIFS(INDEX(前期_2026!$D$2:$Z$300,0,MATCH($C18,前期_2026!$D$1:$Z$1,0)),前期_2026!$A$2:$A$300,"標打",前期_2026!$B$2:$B$300,"All Iscfm",前期_2026!$C$2:$C$300,$B18),0) -> 32195.7 | G18: =E18-F18 -> 0 | H18: =IF(F18=0,"",G18/F18) -> 0 | I18: =IFERROR(SUMIFS(INDEX(本週_2026!$D$2:$Z$300,0,MATCH($C18,本週_2026!$D$1:$Z$1,0)),本週_2026!$A$2:$A$300,"NET_CMT_標打_成改後",本週_2026!$B$2:$B$300,"All Iscfm",本週_2026!$C$2:$C$300,$B18),0) -> 17.46 | J18: =IFERROR(SUMIFS(INDEX(前期_2026!$D$2:$Z$300,0,MATCH($C18,前期_2026!$D$1:$Z$1,0)),前期_2026!$A$2:$A$300,"NET_CMT_標打_成改後",前期_2026!$B$2:$B$300,"All Iscfm",前期_2026!$C$2:$C$300,$B18),0) -> 17.46 | K18: =I18-J18 -> 0 | L18: =IF($B18="All Program","",IF(OR(ABS(G18)>=說明!$C$7,ABS(K18)>=說明!$C$8),"需說明","")) | M18: =IF(L18="需說明",COUNTIF($L$5:L18,"需說明"),"")
A19: 2026 | B19: SEASONAL-SWEATER | C19: 2026-Q4 | D19: Q4 | E19: =IFERROR(SUMIFS(INDEX(本週_2026!$D$2:$Z$300,0,MATCH($C19,本週_2026!$D$1:$Z$1,0)),本週_2026!$A$2:$A$300,"標打",本週_2026!$B$2:$B$300,"All Iscfm",本週_2026!$C$2:$C$300,$B19),0) -> 28767.8 | F19: =IFERROR(SUMIFS(INDEX(前期_2026!$D$2:$Z$300,0,MATCH($C19,前期_2026!$D$1:$Z$1,0)),前期_2026!$A$2:$A$300,"標打",前期_2026!$B$2:$B$300,"All Iscfm",前期_2026!$C$2:$C$300,$B19),0) -> 28767.8 | G19: =E19-F19 -> 0 | H19: =IF(F19=0,"",G19/F19) -> 0 | I19: =IFERROR(SUMIFS(INDEX(本週_2026!$D$2:$Z$300,0,MATCH($C19,本週_2026!$D$1:$Z$1,0)),本週_2026!$A$2:$A$300,"NET_CMT_標打_成改後",本週_2026!$B$2:$B$300,"All Iscfm",本週_2026!$C$2:$C$300,$B19),0) -> 17.96 | J19: =IFERROR(SUMIFS(INDEX(前期_2026!$D$2:$Z$300,0,MATCH($C19,前期_2026!$D$1:$Z$1,0)),前期_2026!$A$2:$A$300,"NET_CMT_標打_成改後",前期_2026!$B$2:$B$300,"All Iscfm",前期_2026!$C$2:$C$300,$B19),0) -> 17.96 | K19: =I19-J19 -> 0 | L19: =IF($B19="All Program","",IF(OR(ABS(G19)>=說明!$C$7,ABS(K19)>=說明!$C$8),"需說明","")) | M19: =IF(L19="需說明",COUNTIF($L$5:L19,"需說明"),"")
A20: 2026 | B20: YEARLY RUN-304ALT | C20: 2026 | D20: 全年 | E20: =IFERROR(SUMIFS(INDEX(本週_2026!$D$2:$Z$300,0,MATCH($C20,本週_2026!$D$1:$Z$1,0)),本週_2026!$A$2:$A$300,"標打",本週_2026!$B$2:$B$300,"All Iscfm",本週_2026!$C$2:$C$300,$B20),0) -> 65495.8 | F20: =IFERROR(SUMIFS(INDEX(前期_2026!$D$2:$Z$300,0,MATCH($C20,前期_2026!$D$1:$Z$1,0)),前期_2026!$A$2:$A$300,"標打",前期_2026!$B$2:$B$300,"All Iscfm",前期_2026!$C$2:$C$300,$B20),0) -> 65495.8 | G20: =E20-F20 -> 0 | H20: =IF(F20=0,"",G20/F20) -> 0 | I20: =IFERROR(SUMIFS(INDEX(本週_2026!$D$2:$Z$300,0,MATCH($C20,本週_2026!$D$1:$Z$1,0)),本週_2026!$A$2:$A$300,"NET_CMT_標打_成改後",本週_2026!$B$2:$B$300,"All Iscfm",本週_2026!$C$2:$C$300,$B20),0) -> 22.68 | J20: =IFERROR(SUMIFS(INDEX(前期_2026!$D$2:$Z$300,0,MATCH($C20,前期_2026!$D$1:$Z$1,0)),前期_2026!$A$2:$A$300,"NET_CMT_標打_成改後",前期_2026!$B$2:$B$300,"All Iscfm",前期_2026!$C$2:$C$300,$B20),0) -> 22.68 | K20: =I20-J20 -> 0 | L20: =IF($B20="All Program","",IF(OR(ABS(G20)>=說明!$C$7,ABS(K20)>=說明!$C$8),"需說明","")) | M20: =IF(L20="需說明",COUNTIF($L$5:L20,"需說明"),"")
A21: 2026 | B21: YEARLY RUN-304ALT | C21: 2026-Q1 | D21: Q1 | E21: =IFERROR(SUMIFS(INDEX(本週_2026!$D$2:$Z$300,0,MATCH($C21,本週_2026!$D$1:$Z$1,0)),本週_2026!$A$2:$A$300,"標打",本週_2026!$B$2:$B$300,"All Iscfm",本週_2026!$C$2:$C$300,$B21),0) -> 25708.7 | F21: =IFERROR(SUMIFS(INDEX(前期_2026!$D$2:$Z$300,0,MATCH($C21,前期_2026!$D$1:$Z$1,0)),前期_2026!$A$2:$A$300,"標打",前期_2026!$B$2:$B$300,"All Iscfm",前期_2026!$C$2:$C$300,$B21),0) -> 25708.7 | G21: =E21-F21 -> 0 | H21: =IF(F21=0,"",G21/F21) -> 0 | I21: =IFERROR(SUMIFS(INDEX(本週_2026!$D$2:$Z$300,0,MATCH($C21,本週_2026!$D$1:$Z$1,0)),本週_2026!$A$2:$A$300,"NET_CMT_標打_成改後",本週_2026!$B$2:$B$300,"All Iscfm",本週_2026!$C$2:$C$300,$B21),0) -> 23.05 | J21: =IFERROR(SUMIFS(INDEX(前期_2026!$D$2:$Z$300,0,MATCH($C21,前期_2026!$D$1:$Z$1,0)),前期_2026!$A$2:$A$300,"NET_CMT_標打_成改後",前期_2026!$B$2:$B$300,"All Iscfm",前期_2026!$C$2:$C$300,$B21),0) -> 23.05 | K21: =I21-J21 -> 0 | L21: =IF($B21="All Program","",IF(OR(ABS(G21)>=說明!$C$7,ABS(K21)>=說明!$C$8),"需說明","")) | M21: =IF(L21="需說明",COUNTIF($L$5:L21,"需說明"),"")
A22: 2026 | B22: YEARLY RUN-304ALT | C22: 2026-Q2 | D22: Q2 | E22: =IFERROR(SUMIFS(INDEX(本週_2026!$D$2:$Z$300,0,MATCH($C22,本週_2026!$D$1:$Z$1,0)),本週_2026!$A$2:$A$300,"標打",本週_2026!$B$2:$B$300,"All Iscfm",本週_2026!$C$2:$C$300,$B22),0) -> 10777.9 | F22: =IFERROR(SUMIFS(INDEX(前期_2026!$D$2:$Z$300,0,MATCH($C22,前期_2026!$D$1:$Z$1,0)),前期_2026!$A$2:$A$300,"標打",前期_2026!$B$2:$B$300,"All Iscfm",前期_2026!$C$2:$C$300,$B22),0) -> 10777.9 | G22: =E22-F22 -> 0 | H22: =IF(F22=0,"",G22/F22) -> 0 | I22: =IFERROR(SUMIFS(INDEX(本週_2026!$D$2:$Z$300,0,MATCH($C22,本週_2026!$D$1:$Z$1,0)),本週_2026!$A$2:$A$300,"NET_CMT_標打_成改後",本週_2026!$B$2:$B$300,"All Iscfm",本週_2026!$C$2:$C$300,$B22),0) -> 23.07 | J22: =IFERROR(SUMIFS(INDEX(前期_2026!$D$2:$Z$300,0,MATCH($C22,前期_2026!$D$1:$Z$1,0)),前期_2026!$A$2:$A$300,"NET_CMT_標打_成改後",前期_2026!$B$2:$B$300,"All Iscfm",前期_2026!$C$2:$C$300,$B22),0) -> 23.07 | K22: =I22-J22 -> 0 | L22: =IF($B22="All Program","",IF(OR(ABS(G22)>=說明!$C$7,ABS(K22)>=說明!$C$8),"需說明","")) | M22: =IF(L22="需說明",COUNTIF($L$5:L22,"需說明"),"")
A23: 2026 | B23: YEARLY RUN-304ALT | C23: 2026-Q3 | D23: Q3 | E23: =IFERROR(SUMIFS(INDEX(本週_2026!$D$2:$Z$300,0,MATCH($C23,本週_2026!$D$1:$Z$1,0)),本週_2026!$A$2:$A$300,"標打",本週_2026!$B$2:$B$300,"All Iscfm",本週_2026!$C$2:$C$300,$B23),0) -> 8722.8 | F23: =IFERROR(SUMIFS(INDEX(前期_2026!$D$2:$Z$300,0,MATCH($C23,前期_2026!$D$1:$Z$1,0)),前期_2026!$A$2:$A$300,"標打",前期_2026!$B$2:$B$300,"All Iscfm",前期_2026!$C$2:$C$300,$B23),0) -> 8722.8 | G23: =E23-F23 -> 0 | H23: =IF(F23=0,"",G23/F23) -> 0 | I23: =IFERROR(SUMIFS(INDEX(本週_2026!$D$2:$Z$300,0,MATCH($C23,本週_2026!$D$1:$Z$1,0)),本週_2026!$A$2:$A$300,"NET_CMT_標打_成改後",本週_2026!$B$2:$B$300,"All Iscfm",本週_2026!$C$2:$C$300,$B23),0) -> 21.5 | J23: =IFERROR(SUMIFS(INDEX(前期_2026!$D$2:$Z$300,0,MATCH($C23,前期_2026!$D$1:$Z$1,0)),前期_2026!$A$2:$A$300,"NET_CMT_標打_成改後",前期_2026!$B$2:$B$300,"All Iscfm",前期_2026!$C$2:$C$300,$B23),0) -> 21.5 | K23: =I23-J23 -> 0 | L23: =IF($B23="All Program","",IF(OR(ABS(G23)>=說明!$C$7,ABS(K23)>=說明!$C$8),"需說明","")) | M23: =IF(L23="需說明",COUNTIF($L$5:L23,"需說明"),"")
A24: 2026 | B24: YEARLY RUN-304ALT | C24: 2026-Q4 | D24: Q4 | E24: =IFERROR(SUMIFS(INDEX(本週_2026!$D$2:$Z$300,0,MATCH($C24,本週_2026!$D$1:$Z$1,0)),本週_2026!$A$2:$A$300,"標打",本週_2026!$B$2:$B$300,"All Iscfm",本週_2026!$C$2:$C$300,$B24),0) -> 20286.5 | F24: =IFERROR(SUMIFS(INDEX(前期_2026!$D$2:$Z$300,0,MATCH($C24,前期_2026!$D$1:$Z$1,0)),前期_2026!$A$2:$A$300,"標打",前期_2026!$B$2:$B$300,"All Iscfm",前期_2026!$C$2:$C$300,$B24),0) -> 20286.5 | G24: =E24-F24 -> 0 | H24: =IF(F24=0,"",G24/F24) -> 0 | I24: =IFERROR(SUMIFS(INDEX(本週_2026!$D$2:$Z$300,0,MATCH($C24,本週_2026!$D$1:$Z$1,0)),本週_2026!$A$2:$A$300,"NET_CMT_標打_成改後",本週_2026!$B$2:$B$300,"All Iscfm",本週_2026!$C$2:$C$300,$B24),0) -> 22.5 | J24: =IFERROR(SUMIFS(INDEX(前期_2026!$D$2:$Z$300,0,MATCH($C24,前期_2026!$D$1:$Z$1,0)),前期_2026!$A$2:$A$300,"NET_CMT_標打_成改後",前期_2026!$B$2:$B$300,"All Iscfm",前期_2026!$C$2:$C$300,$B24),0) -> 22.5 | K24: =I24-J24 -> 0 | L24: =IF($B24="All Program","",IF(OR(ABS(G24)>=說明!$C$7,ABS(K24)>=說明!$C$8),"需說明","")) | M24: =IF(L24="需說明",COUNTIF($L$5:L24,"需說明"),"")
A25: 2026 | B25: YEARLY RUN-ACT300 | C25: 2026 | D25: 全年 | E25: =IFERROR(SUMIFS(INDEX(本週_2026!$D$2:$Z$300,0,MATCH($C25,本週_2026!$D$1:$Z$1,0)),本週_2026!$A$2:$A$300,"標打",本週_2026!$B$2:$B$300,"All Iscfm",本週_2026!$C$2:$C$300,$B25),0) -> 576887 | F25: =IFERROR(SUMIFS(INDEX(前期_2026!$D$2:$Z$300,0,MATCH($C25,前期_2026!$D$1:$Z$1,0)),前期_2026!$A$2:$A$300,"標打",前期_2026!$B$2:$B$300,"All Iscfm",前期_2026!$C$2:$C$300,$B25),0) -> 576887 | G25: =E25-F25 -> 0 | H25: =IF(F25=0,"",G25/F25) -> 0 | I25: =IFERROR(SUMIFS(INDEX(本週_2026!$D$2:$Z$300,0,MATCH($C25,本週_2026!$D$1:$Z$1,0)),本週_2026!$A$2:$A$300,"NET_CMT_標打_成改後",本週_2026!$B$2:$B$300,"All Iscfm",本週_2026!$C$2:$C$300,$B25),0) -> 19.31 | J25: =IFERROR(SUMIFS(INDEX(前期_2026!$D$2:$Z$300,0,MATCH($C25,前期_2026!$D$1:$Z$1,0)),前期_2026!$A$2:$A$300,"NET_CMT_標打_成改後",前期_2026!$B$2:$B$300,"All Iscfm",前期_2026!$C$2:$C$300,$B25),0) -> 19.31 | K25: =I25-J25 -> 0 | L25: =IF($B25="All Program","",IF(OR(ABS(G25)>=說明!$C$7,ABS(K25)>=說明!$C$8),"需說明","")) | M25: =IF(L25="需說明",COUNTIF($L$5:L25,"需說明"),"")
A26: 2026 | B26: YEARLY RUN-ACT300 | C26: 2026-Q1 | D26: Q1 | E26: =IFERROR(SUMIFS(INDEX(本週_2026!$D$2:$Z$300,0,MATCH($C26,本週_2026!$D$1:$Z$1,0)),本週_2026!$A$2:$A$300,"標打",本週_2026!$B$2:$B$300,"All Iscfm",本週_2026!$C$2:$C$300,$B26),0) -> 128117.1 | F26: =IFERROR(SUMIFS(INDEX(前期_2026!$D$2:$Z$300,0,MATCH($C26,前期_2026!$D$1:$Z$1,0)),前期_2026!$A$2:$A$300,"標打",前期_2026!$B$2:$B$300,"All Iscfm",前期_2026!$C$2:$C$300,$B26),0) -> 128117.1 | G26: =E26-F26 -> 0 | H26: =IF(F26=0,"",G26/F26) -> 0 | I26: =IFERROR(SUMIFS(INDEX(本週_2026!$D$2:$Z$300,0,MATCH($C26,本週_2026!$D$1:$Z$1,0)),本週_2026!$A$2:$A$300,"NET_CMT_標打_成改後",本週_2026!$B$2:$B$300,"All Iscfm",本週_2026!$C$2:$C$300,$B26),0) -> 20.21 | J26: =IFERROR(SUMIFS(INDEX(前期_2026!$D$2:$Z$300,0,MATCH($C26,前期_2026!$D$1:$Z$1,0)),前期_2026!$A$2:$A$300,"NET_CMT_標打_成改後",前期_2026!$B$2:$B$300,"All Iscfm",前期_2026!$C$2:$C$300,$B26),0) -> 20.21 | K26: =I26-J26 -> 0 | L26: =IF($B26="All Program","",IF(OR(ABS(G26)>=說明!$C$7,ABS(K26)>=說明!$C$8),"需說明","")) | M26: =IF(L26="需說明",COUNTIF($L$5:L26,"需說明"),"")
A27: 2026 | B27: YEARLY RUN-ACT300 | C27: 2026-Q2 | D27: Q2 | E27: =IFERROR(SUMIFS(INDEX(本週_2026!$D$2:$Z$300,0,MATCH($C27,本週_2026!$D$1:$Z$1,0)),本週_2026!$A$2:$A$300,"標打",本週_2026!$B$2:$B$300,"All Iscfm",本週_2026!$C$2:$C$300,$B27),0) -> 159076.9 | F27: =IFERROR(SUMIFS(INDEX(前期_2026!$D$2:$Z$300,0,MATCH($C27,前期_2026!$D$1:$Z$1,0)),前期_2026!$A$2:$A$300,"標打",前期_2026!$B$2:$B$300,"All Iscfm",前期_2026!$C$2:$C$300,$B27),0) -> 159076.9 | G27: =E27-F27 -> 0 | H27: =IF(F27=0,"",G27/F27) -> 0 | I27: =IFERROR(SUMIFS(INDEX(本週_2026!$D$2:$Z$300,0,MATCH($C27,本週_2026!$D$1:$Z$1,0)),本週_2026!$A$2:$A$300,"NET_CMT_標打_成改後",本週_2026!$B$2:$B$300,"All Iscfm",本週_2026!$C$2:$C$300,$B27),0) -> 19.62 | J27: =IFERROR(SUMIFS(INDEX(前期_2026!$D$2:$Z$300,0,MATCH($C27,前期_2026!$D$1:$Z$1,0)),前期_2026!$A$2:$A$300,"NET_CMT_標打_成改後",前期_2026!$B$2:$B$300,"All Iscfm",前期_2026!$C$2:$C$300,$B27),0) -> 19.62 | K27: =I27-J27 -> 0 | L27: =IF($B27="All Program","",IF(OR(ABS(G27)>=說明!$C$7,ABS(K27)>=說明!$C$8),"需說明","")) | M27: =IF(L27="需說明",COUNTIF($L$5:L27,"需說明"),"")
A28: 2026 | B28: YEARLY RUN-ACT300 | C28: 2026-Q3 | D28: Q3 | E28: =IFERROR(SUMIFS(INDEX(本週_2026!$D$2:$Z$300,0,MATCH($C28,本週_2026!$D$1:$Z$1,0)),本週_2026!$A$2:$A$300,"標打",本週_2026!$B$2:$B$300,"All Iscfm",本週_2026!$C$2:$C$300,$B28),0) -> 173112.2 | F28: =IFERROR(SUMIFS(INDEX(前期_2026!$D$2:$Z$300,0,MATCH($C28,前期_2026!$D$1:$Z$1,0)),前期_2026!$A$2:$A$300,"標打",前期_2026!$B$2:$B$300,"All Iscfm",前期_2026!$C$2:$C$300,$B28),0) -> 173112.2 | G28: =E28-F28 -> 0 | H28: =IF(F28=0,"",G28/F28) -> 0 | I28: =IFERROR(SUMIFS(INDEX(本週_2026!$D$2:$Z$300,0,MATCH($C28,本週_2026!$D$1:$Z$1,0)),本週_2026!$A$2:$A$300,"NET_CMT_標打_成改後",本週_2026!$B$2:$B$300,"All Iscfm",本週_2026!$C$2:$C$300,$B28),0) -> 18.6 | J28: =IFERROR(SUMIFS(INDEX(前期_2026!$D$2:$Z$300,0,MATCH($C28,前期_2026!$D$1:$Z$1,0)),前期_2026!$A$2:$A$300,"NET_CMT_標打_成改後",前期_2026!$B$2:$B$300,"All Iscfm",前期_2026!$C$2:$C$300,$B28),0) -> 18.6 | K28: =I28-J28 -> 0 | L28: =IF($B28="All Program","",IF(OR(ABS(G28)>=說明!$C$7,ABS(K28)>=說明!$C$8),"需說明","")) | M28: =IF(L28="需說明",COUNTIF($L$5:L28,"需說明"),"")
A29: 2026 | B29: YEARLY RUN-ACT300 | C29: 2026-Q4 | D29: Q4 | E29: =IFERROR(SUMIFS(INDEX(本週_2026!$D$2:$Z$300,0,MATCH($C29,本週_2026!$D$1:$Z$1,0)),本週_2026!$A$2:$A$300,"標打",本週_2026!$B$2:$B$300,"All Iscfm",本週_2026!$C$2:$C$300,$B29),0) -> 116580.8 | F29: =IFERROR(SUMIFS(INDEX(前期_2026!$D$2:$Z$300,0,MATCH($C29,前期_2026!$D$1:$Z$1,0)),前期_2026!$A$2:$A$300,"標打",前期_2026!$B$2:$B$300,"All Iscfm",前期_2026!$C$2:$C$300,$B29),0) -> 116580.8 | G29: =E29-F29 -> 0 | H29: =IF(F29=0,"",G29/F29) -> 0 | I29: =IFERROR(SUMIFS(INDEX(本週_2026!$D$2:$Z$300,0,MATCH($C29,本週_2026!$D$1:$Z$1,0)),本週_2026!$A$2:$A$300,"NET_CMT_標打_成改後",本週_2026!$B$2:$B$300,"All Iscfm",本週_2026!$C$2:$C$300,$B29),0) -> 18.97 | J29: =IFERROR(SUMIFS(INDEX(前期_2026!$D$2:$Z$300,0,MATCH($C29,前期_2026!$D$1:$Z$1,0)),前期_2026!$A$2:$A$300,"NET_CMT_標打_成改後",前期_2026!$B$2:$B$300,"All Iscfm",前期_2026!$C$2:$C$300,$B29),0) -> 18.97 | K29: =I29-J29 -> 0 | L29: =IF($B29="All Program","",IF(OR(ABS(G29)>=說明!$C$7,ABS(K29)>=說明!$C$8),"需說明","")) | M29: =IF(L29="需說明",COUNTIF($L$5:L29,"需說明"),"")
A30: 2026 | B30: YEARLY RUN-AIT350 | C30: 2026 | D30: 全年 | E30: =IFERROR(SUMIFS(INDEX(本週_2026!$D$2:$Z$300,0,MATCH($C30,本週_2026!$D$1:$Z$1,0)),本週_2026!$A$2:$A$300,"標打",本週_2026!$B$2:$B$300,"All Iscfm",本週_2026!$C$2:$C$300,$B30),0) -> 21370.6 | F30: =IFERROR(SUMIFS(INDEX(前期_2026!$D$2:$Z$300,0,MATCH($C30,前期_2026!$D$1:$Z$1,0)),前期_2026!$A$2:$A$300,"標打",前期_2026!$B$2:$B$300,"All Iscfm",前期_2026!$C$2:$C$300,$B30),0) -> 21370.6 | G30: =E30-F30 -> 0 | H30: =IF(F30=0,"",G30/F30) -> 0 | I30: =IFERROR(SUMIFS(INDEX(本週_2026!$D$2:$Z$300,0,MATCH($C30,本週_2026!$D$1:$Z$1,0)),本週_2026!$A$2:$A$300,"NET_CMT_標打_成改後",本週_2026!$B$2:$B$300,"All Iscfm",本週_2026!$C$2:$C$300,$B30),0) -> 20.7 | J30: =IFERROR(SUMIFS(INDEX(前期_2026!$D$2:$Z$300,0,MATCH($C30,前期_2026!$D$1:$Z$1,0)),前期_2026!$A$2:$A$300,"NET_CMT_標打_成改後",前期_2026!$B$2:$B$300,"All Iscfm",前期_2026!$C$2:$C$300,$B30),0) -> 20.7 | K30: =I30-J30 -> 0 | L30: =IF($B30="All Program","",IF(OR(ABS(G30)>=說明!$C$7,ABS(K30)>=說明!$C$8),"需說明","")) | M30: =IF(L30="需說明",COUNTIF($L$5:L30,"需說明"),"")
A31: 2026 | B31: YEARLY RUN-AIT350 | C31: 2026-Q1 | D31: Q1 | E31: =IFERROR(SUMIFS(INDEX(本週_2026!$D$2:$Z$300,0,MATCH($C31,本週_2026!$D$1:$Z$1,0)),本週_2026!$A$2:$A$300,"標打",本週_2026!$B$2:$B$300,"All Iscfm",本週_2026!$C$2:$C$300,$B31),0) -> 6650.7 | F31: =IFERROR(SUMIFS(INDEX(前期_2026!$D$2:$Z$300,0,MATCH($C31,前期_2026!$D$1:$Z$1,0)),前期_2026!$A$2:$A$300,"標打",前期_2026!$B$2:$B$300,"All Iscfm",前期_2026!$C$2:$C$300,$B31),0) -> 6650.7 | G31: =E31-F31 -> 0 | H31: =IF(F31=0,"",G31/F31) -> 0 | I31: =IFERROR(SUMIFS(INDEX(本週_2026!$D$2:$Z$300,0,MATCH($C31,本週_2026!$D$1:$Z$1,0)),本週_2026!$A$2:$A$300,"NET_CMT_標打_成改後",本週_2026!$B$2:$B$300,"All Iscfm",本週_2026!$C$2:$C$300,$B31),0) -> 21.52 | J31: =IFERROR(SUMIFS(INDEX(前期_2026!$D$2:$Z$300,0,MATCH($C31,前期_2026!$D$1:$Z$1,0)),前期_2026!$A$2:$A$300,"NET_CMT_標打_成改後",前期_2026!$B$2:$B$300,"All Iscfm",前期_2026!$C$2:$C$300,$B31),0) -> 21.52 | K31: =I31-J31 -> 0 | L31: =IF($B31="All Program","",IF(OR(ABS(G31)>=說明!$C$7,ABS(K31)>=說明!$C$8),"需說明","")) | M31: =IF(L31="需說明",COUNTIF($L$5:L31,"需說明"),"")
A32: 2026 | B32: YEARLY RUN-AIT350 | C32: 2026-Q2 | D32: Q2 | E32: =IFERROR(SUMIFS(INDEX(本週_2026!$D$2:$Z$300,0,MATCH($C32,本週_2026!$D$1:$Z$1,0)),本週_2026!$A$2:$A$300,"標打",本週_2026!$B$2:$B$300,"All Iscfm",本週_2026!$C$2:$C$300,$B32),0) -> 3931.3 | F32: =IFERROR(SUMIFS(INDEX(前期_2026!$D$2:$Z$300,0,MATCH($C32,前期_2026!$D$1:$Z$1,0)),前期_2026!$A$2:$A$300,"標打",前期_2026!$B$2:$B$300,"All Iscfm",前期_2026!$C$2:$C$300,$B32),0) -> 3931.3 | G32: =E32-F32 -> 0 | H32: =IF(F32=0,"",G32/F32) -> 0 | I32: =IFERROR(SUMIFS(INDEX(本週_2026!$D$2:$Z$300,0,MATCH($C32,本週_2026!$D$1:$Z$1,0)),本週_2026!$A$2:$A$300,"NET_CMT_標打_成改後",本週_2026!$B$2:$B$300,"All Iscfm",本週_2026!$C$2:$C$300,$B32),0) -> 20.77 | J32: =IFERROR(SUMIFS(INDEX(前期_2026!$D$2:$Z$300,0,MATCH($C32,前期_2026!$D$1:$Z$1,0)),前期_2026!$A$2:$A$300,"NET_CMT_標打_成改後",前期_2026!$B$2:$B$300,"All Iscfm",前期_2026!$C$2:$C$300,$B32),0) -> 20.77 | K32: =I32-J32 -> 0 | L32: =IF($B32="All Program","",IF(OR(ABS(G32)>=說明!$C$7,ABS(K32)>=說明!$C$8),"需說明","")) | M32: =IF(L32="需說明",COUNTIF($L$5:L32,"需說明"),"")
A33: 2026 | B33: YEARLY RUN-AIT350 | C33: 2026-Q3 | D33: Q3 | E33: =IFERROR(SUMIFS(INDEX(本週_2026!$D$2:$Z$300,0,MATCH($C33,本週_2026!$D$1:$Z$1,0)),本週_2026!$A$2:$A$300,"標打",本週_2026!$B$2:$B$300,"All Iscfm",本週_2026!$C$2:$C$300,$B33),0) -> 5155.3 | F33: =IFERROR(SUMIFS(INDEX(前期_2026!$D$2:$Z$300,0,MATCH($C33,前期_2026!$D$1:$Z$1,0)),前期_2026!$A$2:$A$300,"標打",前期_2026!$B$2:$B$300,"All Iscfm",前期_2026!$C$2:$C$300,$B33),0) -> 5155.3 | G33: =E33-F33 -> 0 | H33: =IF(F33=0,"",G33/F33) -> 0 | I33: =IFERROR(SUMIFS(INDEX(本週_2026!$D$2:$Z$300,0,MATCH($C33,本週_2026!$D$1:$Z$1,0)),本週_2026!$A$2:$A$300,"NET_CMT_標打_成改後",本週_2026!$B$2:$B$300,"All Iscfm",本週_2026!$C$2:$C$300,$B33),0) -> 20.31 | J33: =IFERROR(SUMIFS(INDEX(前期_2026!$D$2:$Z$300,0,MATCH($C33,前期_2026!$D$1:$Z$1,0)),前期_2026!$A$2:$A$300,"NET_CMT_標打_成改後",前期_2026!$B$2:$B$300,"All Iscfm",前期_2026!$C$2:$C$300,$B33),0) -> 20.31 | K33: =I33-J33 -> 0 | L33: =IF($B33="All Program","",IF(OR(ABS(G33)>=說明!$C$7,ABS(K33)>=說明!$C$8),"需說明","")) | M33: =IF(L33="需說明",COUNTIF($L$5:L33,"需說明"),"")
A34: 2026 | B34: YEARLY RUN-AIT350 | C34: 2026-Q4 | D34: Q4 | E34: =IFERROR(SUMIFS(INDEX(本週_2026!$D$2:$Z$300,0,MATCH($C34,本週_2026!$D$1:$Z$1,0)),本週_2026!$A$2:$A$300,"標打",本週_2026!$B$2:$B$300,"All Iscfm",本週_2026!$C$2:$C$300,$B34),0) -> 5633.3 | F34: =IFERROR(SUMIFS(INDEX(前期_2026!$D$2:$Z$300,0,MATCH($C34,前期_2026!$D$1:$Z$1,0)),前期_2026!$A$2:$A$300,"標打",前期_2026!$B$2:$B$300,"All Iscfm",前期_2026!$C$2:$C$300,$B34),0) -> 5633.3 | G34: =E34-F34 -> 0 | H34: =IF(F34=0,"",G34/F34) -> 0 | I34: =IFERROR(SUMIFS(INDEX(本週_2026!$D$2:$Z$300,0,MATCH($C34,本週_2026!$D$1:$Z$1,0)),本週_2026!$A$2:$A$300,"NET_CMT_標打_成改後",本週_2026!$B$2:$B$300,"All Iscfm",本週_2026!$C$2:$C$300,$B34),0) -> 20.06 | J34: =IFERROR(SUMIFS(INDEX(前期_2026!$D$2:$Z$300,0,MATCH($C34,前期_2026!$D$1:$Z$1,0)),前期_2026!$A$2:$A$300,"NET_CMT_標打_成改後",前期_2026!$B$2:$B$300,"All Iscfm",前期_2026!$C$2:$C$300,$B34),0) -> 20.06 | K34: =I34-J34 -> 0 | L34: =IF($B34="All Program","",IF(OR(ABS(G34)>=說明!$C$7,ABS(K34)>=說明!$C$8),"需說明","")) | M34: =IF(L34="需說明",COUNTIF($L$5:L34,"需說明"),"")
A35: 2026 | B35: YEARLY RUN-POLO | C35: 2026 | D35: 全年 | E35: =IFERROR(SUMIFS(INDEX(本週_2026!$D$2:$Z$300,0,MATCH($C35,本週_2026!$D$1:$Z$1,0)),本週_2026!$A$2:$A$300,"標打",本週_2026!$B$2:$B$300,"All Iscfm",本週_2026!$C$2:$C$300,$B35),0) -> 162693.9 | F35: =IFERROR(SUMIFS(INDEX(前期_2026!$D$2:$Z$300,0,MATCH($C35,前期_2026!$D$1:$Z$1,0)),前期_2026!$A$2:$A$300,"標打",前期_2026!$B$2:$B$300,"All Iscfm",前期_2026!$C$2:$C$300,$B35),0) -> 162693.9 | G35: =E35-F35 -> 0 | H35: =IF(F35=0,"",G35/F35) -> 0 | I35: =IFERROR(SUMIFS(INDEX(本週_2026!$D$2:$Z$300,0,MATCH($C35,本週_2026!$D$1:$Z$1,0)),本週_2026!$A$2:$A$300,"NET_CMT_標打_成改後",本週_2026!$B$2:$B$300,"All Iscfm",本週_2026!$C$2:$C$300,$B35),0) -> 17.29 | J35: =IFERROR(SUMIFS(INDEX(前期_2026!$D$2:$Z$300,0,MATCH($C35,前期_2026!$D$1:$Z$1,0)),前期_2026!$A$2:$A$300,"NET_CMT_標打_成改後",前期_2026!$B$2:$B$300,"All Iscfm",前期_2026!$C$2:$C$300,$B35),0) -> 17.29 | K35: =I35-J35 -> 0 | L35: =IF($B35="All Program","",IF(OR(ABS(G35)>=說明!$C$7,ABS(K35)>=說明!$C$8),"需說明","")) | M35: =IF(L35="需說明",COUNTIF($L$5:L35,"需說明"),"")
A36: 2026 | B36: YEARLY RUN-POLO | C36: 2026-Q1 | D36: Q1 | E36: =IFERROR(SUMIFS(INDEX(本週_2026!$D$2:$Z$300,0,MATCH($C36,本週_2026!$D$1:$Z$1,0)),本週_2026!$A$2:$A$300,"標打",本週_2026!$B$2:$B$300,"All Iscfm",本週_2026!$C$2:$C$300,$B36),0) -> 15789.4 | F36: =IFERROR(SUMIFS(INDEX(前期_2026!$D$2:$Z$300,0,MATCH($C36,前期_2026!$D$1:$Z$1,0)),前期_2026!$A$2:$A$300,"標打",前期_2026!$B$2:$B$300,"All Iscfm",前期_2026!$C$2:$C$300,$B36),0) -> 15789.4 | G36: =E36-F36 -> 0 | H36: =IF(F36=0,"",G36/F36) -> 0 | I36: =IFERROR(SUMIFS(INDEX(本週_2026!$D$2:$Z$300,0,MATCH($C36,本週_2026!$D$1:$Z$1,0)),本週_2026!$A$2:$A$300,"NET_CMT_標打_成改後",本週_2026!$B$2:$B$300,"All Iscfm",本週_2026!$C$2:$C$300,$B36),0) -> 18.26 | J36: =IFERROR(SUMIFS(INDEX(前期_2026!$D$2:$Z$300,0,MATCH($C36,前期_2026!$D$1:$Z$1,0)),前期_2026!$A$2:$A$300,"NET_CMT_標打_成改後",前期_2026!$B$2:$B$300,"All Iscfm",前期_2026!$C$2:$C$300,$B36),0) -> 18.26 | K36: =I36-J36 -> 0 | L36: =IF($B36="All Program","",IF(OR(ABS(G36)>=說明!$C$7,ABS(K36)>=說明!$C$8),"需說明","")) | M36: =IF(L36="需說明",COUNTIF($L$5:L36,"需說明"),"")
A37: 2026 | B37: YEARLY RUN-POLO | C37: 2026-Q2 | D37: Q2 | E37: =IFERROR(SUMIFS(INDEX(本週_2026!$D$2:$Z$300,0,MATCH($C37,本週_2026!$D$1:$Z$1,0)),本週_2026!$A$2:$A$300,"標打",本週_2026!$B$2:$B$300,"All Iscfm",本週_2026!$C$2:$C$300,$B37),0) -> 34291.3 | F37: =IFERROR(SUMIFS(INDEX(前期_2026!$D$2:$Z$300,0,MATCH($C37,前期_2026!$D$1:$Z$1,0)),前期_2026!$A$2:$A$300,"標打",前期_2026!$B$2:$B$300,"All Iscfm",前期_2026!$C$2:$C$300,$B37),0) -> 34291.3 | G37: =E37-F37 -> 0 | H37: =IF(F37=0,"",G37/F37) -> 0 | I37: =IFERROR(SUMIFS(INDEX(本週_2026!$D$2:$Z$300,0,MATCH($C37,本週_2026!$D$1:$Z$1,0)),本週_2026!$A$2:$A$300,"NET_CMT_標打_成改後",本週_2026!$B$2:$B$300,"All Iscfm",本週_2026!$C$2:$C$300,$B37),0) -> 17.66 | J37: =IFERROR(SUMIFS(INDEX(前期_2026!$D$2:$Z$300,0,MATCH($C37,前期_2026!$D$1:$Z$1,0)),前期_2026!$A$2:$A$300,"NET_CMT_標打_成改後",前期_2026!$B$2:$B$300,"All Iscfm",前期_2026!$C$2:$C$300,$B37),0) -> 17.66 | K37: =I37-J37 -> 0 | L37: =IF($B37="All Program","",IF(OR(ABS(G37)>=說明!$C$7,ABS(K37)>=說明!$C$8),"需說明","")) | M37: =IF(L37="需說明",COUNTIF($L$5:L37,"需說明"),"")
A38: 2026 | B38: YEARLY RUN-POLO | C38: 2026-Q3 | D38: Q3 | E38: =IFERROR(SUMIFS(INDEX(本週_2026!$D$2:$Z$300,0,MATCH($C38,本週_2026!$D$1:$Z$1,0)),本週_2026!$A$2:$A$300,"標打",本週_2026!$B$2:$B$300,"All Iscfm",本週_2026!$C$2:$C$300,$B38),0) -> 51757.4 | F38: =IFERROR(SUMIFS(INDEX(前期_2026!$D$2:$Z$300,0,MATCH($C38,前期_2026!$D$1:$Z$1,0)),前期_2026!$A$2:$A$300,"標打",前期_2026!$B$2:$B$300,"All Iscfm",前期_2026!$C$2:$C$300,$B38),0) -> 51757.4 | G38: =E38-F38 -> 0 | H38: =IF(F38=0,"",G38/F38) -> 0 | I38: =IFERROR(SUMIFS(INDEX(本週_2026!$D$2:$Z$300,0,MATCH($C38,本週_2026!$D$1:$Z$1,0)),本週_2026!$A$2:$A$300,"NET_CMT_標打_成改後",本週_2026!$B$2:$B$300,"All Iscfm",本週_2026!$C$2:$C$300,$B38),0) -> 16.93 | J38: =IFERROR(SUMIFS(INDEX(前期_2026!$D$2:$Z$300,0,MATCH($C38,前期_2026!$D$1:$Z$1,0)),前期_2026!$A$2:$A$300,"NET_CMT_標打_成改後",前期_2026!$B$2:$B$300,"All Iscfm",前期_2026!$C$2:$C$300,$B38),0) -> 16.93 | K38: =I38-J38 -> 0 | L38: =IF($B38="All Program","",IF(OR(ABS(G38)>=說明!$C$7,ABS(K38)>=說明!$C$8),"需說明","")) | M38: =IF(L38="需說明",COUNTIF($L$5:L38,"需說明"),"")
A39: 2026 | B39: YEARLY RUN-POLO | C39: 2026-Q4 | D39: Q4 | E39: =IFERROR(SUMIFS(INDEX(本週_2026!$D$2:$Z$300,0,MATCH($C39,本週_2026!$D$1:$Z$1,0)),本週_2026!$A$2:$A$300,"標打",本週_2026!$B$2:$B$300,"All Iscfm",本週_2026!$C$2:$C$300,$B39),0) -> 60855.8 | F39: =IFERROR(SUMIFS(INDEX(前期_2026!$D$2:$Z$300,0,MATCH($C39,前期_2026!$D$1:$Z$1,0)),前期_2026!$A$2:$A$300,"標打",前期_2026!$B$2:$B$300,"All Iscfm",前期_2026!$C$2:$C$300,$B39),0) -> 60855.8 | G39: =E39-F39 -> 0 | H39: =IF(F39=0,"",G39/F39) -> 0 | I39: =IFERROR(SUMIFS(INDEX(本週_2026!$D$2:$Z$300,0,MATCH($C39,本週_2026!$D$1:$Z$1,0)),本週_2026!$A$2:$A$300,"NET_CMT_標打_成改後",本週_2026!$B$2:$B$300,"All Iscfm",本週_2026!$C$2:$C$300,$B39),0) -> 17.15 | J39: =IFERROR(SUMIFS(INDEX(前期_2026!$D$2:$Z$300,0,MATCH($C39,前期_2026!$D$1:$Z$1,0)),前期_2026!$A$2:$A$300,"NET_CMT_標打_成改後",前期_2026!$B$2:$B$300,"All Iscfm",前期_2026!$C$2:$C$300,$B39),0) -> 17.15 | K39: =I39-J39 -> 0 | L39: =IF($B39="All Program","",IF(OR(ABS(G39)>=說明!$C$7,ABS(K39)>=說明!$C$8),"需說明","")) | M39: =IF(L39="需說明",COUNTIF($L$5:L39,"需說明"),"")
A40: 2027 | B40: All Program | C40: 2027 | D40: 全年 | E40: =IFERROR(SUMIFS(INDEX(本週_2027!$D$2:$Z$300,0,MATCH($C40,本週_2027!$D$1:$Z$1,0)),本週_2027!$A$2:$A$300,"標打",本週_2027!$B$2:$B$300,"All Iscfm",本週_2027!$C$2:$C$300,$B40),0) -> 884101.9 | F40: =IFERROR(SUMIFS(INDEX(前期_2027!$D$2:$Z$300,0,MATCH($C40,前期_2027!$D$1:$Z$1,0)),前期_2027!$A$2:$A$300,"標打",前期_2027!$B$2:$B$300,"All Iscfm",前期_2027!$C$2:$C$300,$B40),0) -> 884101.9 | G40: =E40-F40 -> 0 | H40: =IF(F40=0,"",G40/F40) -> 0 | I40: =IFERROR(SUMIFS(INDEX(本週_2027!$D$2:$Z$300,0,MATCH($C40,本週_2027!$D$1:$Z$1,0)),本週_2027!$A$2:$A$300,"NET_CMT_標打_成改後",本週_2027!$B$2:$B$300,"All Iscfm",本週_2027!$C$2:$C$300,$B40),0) -> 18.75 | J40: =IFERROR(SUMIFS(INDEX(前期_2027!$D$2:$Z$300,0,MATCH($C40,前期_2027!$D$1:$Z$1,0)),前期_2027!$A$2:$A$300,"NET_CMT_標打_成改後",前期_2027!$B$2:$B$300,"All Iscfm",前期_2027!$C$2:$C$300,$B40),0) -> 18.75 | K40: =I40-J40 -> 0 | L40: =IF($B40="All Program","",IF(OR(ABS(G40)>=說明!$C$7,ABS(K40)>=說明!$C$8),"需說明","")) | M40: =IF(L40="需說明",COUNTIF($L$5:L40,"需說明"),"")
A41: 2027 | B41: All Program | C41: 2027-Q1 | D41: Q1 | E41: =IFERROR(SUMIFS(INDEX(本週_2027!$D$2:$Z$300,0,MATCH($C41,本週_2027!$D$1:$Z$1,0)),本週_2027!$A$2:$A$300,"標打",本週_2027!$B$2:$B$300,"All Iscfm",本週_2027!$C$2:$C$300,$B41),0) -> 180615.5 | F41: =IFERROR(SUMIFS(INDEX(前期_2027!$D$2:$Z$300,0,MATCH($C41,前期_2027!$D$1:$Z$1,0)),前期_2027!$A$2:$A$300,"標打",前期_2027!$B$2:$B$300,"All Iscfm",前期_2027!$C$2:$C$300,$B41),0) -> 180615.5 | G41: =E41-F41 -> 0 | H41: =IF(F41=0,"",G41/F41) -> 0 | I41: =IFERROR(SUMIFS(INDEX(本週_2027!$D$2:$Z$300,0,MATCH($C41,本週_2027!$D$1:$Z$1,0)),本週_2027!$A$2:$A$300,"NET_CMT_標打_成改後",本週_2027!$B$2:$B$300,"All Iscfm",本週_2027!$C$2:$C$300,$B41),0) -> 18.73 | J41: =IFERROR(SUMIFS(INDEX(前期_2027!$D$2:$Z$300,0,MATCH($C41,前期_2027!$D$1:$Z$1,0)),前期_2027!$A$2:$A$300,"NET_CMT_標打_成改後",前期_2027!$B$2:$B$300,"All Iscfm",前期_2027!$C$2:$C$300,$B41),0) -> 18.73 | K41: =I41-J41 -> 0 | L41: =IF($B41="All Program","",IF(OR(ABS(G41)>=說明!$C$7,ABS(K41)>=說明!$C$8),"需說明","")) | M41: =IF(L41="需說明",COUNTIF($L$5:L41,"需說明"),"")
...

Sheet 本週_2026
D1: 2026 | E1: 2026-Q1 | F1: 2026-Q2 | G1: 2026-Q3 | H1: 2026-Q4
A2: 標打 | B2: All Iscfm | C2: All Program | D2: 988688.2 | E2: 206294.1 | F2: 243675.4 | G2: 288629.2 | H2: 250089.5
A3: 標打 | B3: All Iscfm | C3: SEASONAL | D3: 66847.8 | E3: 9432.4 | F3: 21764.2 | G3: 17685.8 | H3: 17965.3
A4: 標打 | B4: All Iscfm | C4: SEASONAL-SWEATER | D4: 95393.1 | E4: 20595.7 | F4: 13833.8 | G4: 32195.7 | H4: 28767.8
A5: 標打 | B5: All Iscfm | C5: YEARLY RUN-304ALT | D5: 65495.8 | E5: 25708.7 | F5: 10777.9 | G5: 8722.8 | H5: 20286.5
A6: 標打 | B6: All Iscfm | C6: YEARLY RUN-ACT300 | D6: 576887 | E6: 128117.1 | F6: 159076.9 | G6: 173112.2 | H6: 116580.8
A7: 標打 | B7: All Iscfm | C7: YEARLY RUN-AIT350 | D7: 21370.6 | E7: 6650.7 | F7: 3931.3 | G7: 5155.3 | H7: 5633.3
A8: 標打 | B8: All Iscfm | C8: YEARLY RUN-POLO | D8: 162693.9 | E8: 15789.4 | F8: 34291.3 | G8: 51757.4 | H8: 60855.8
A9: NET_CMT_標打_成改後 | B9: All Iscfm | C9: All Program | D9: 19.16 | E9: 20.33 | F9: 19.57 | G9: 18.32 | H9: 18.77
A10: NET_CMT_標打_成改後 | B10: All Iscfm | C10: SEASONAL | D10: 20.09 | E10: 20.54 | F10: 21.05 | G10: 19.11 | H10: 19.66
A11: NET_CMT_標打_成改後 | B11: All Iscfm | C11: SEASONAL-SWEATER | D11: 17.93 | E11: 18.64 | F11: 17.89 | G11: 17.46 | H11: 17.96
A12: NET_CMT_標打_成改後 | B12: All Iscfm | C12: YEARLY RUN-304ALT | D12: 22.68 | E12: 23.05 | F12: 23.07 | G12: 21.5 | H12: 22.5
A13: NET_CMT_標打_成改後 | B13: All Iscfm | C13: YEARLY RUN-ACT300 | D13: 19.31 | E13: 20.21 | F13: 19.62 | G13: 18.6 | H13: 18.97
... A15: NET_CMT_標打_成改後 | B15: All Iscfm | C15: YEARLY RUN-POLO | D15: 17.29 | E15: 18.26 | F15: 17.66 | G15: 16.93 | H15: 17.15

Sheet 本週_2027
D1: 2027 | E1: 2027-Q1 | F1: 46388 | G1: 46419 | H1: 46447 | I1: 2027-Q2 | J1: 2027-Q3 | K1: 2027-Q4
A2: 標打 | B2: All Iscfm | C2: All Program | D2: 884101.9 | E2: 180615.5 | F2: 73736.5 | G2: 35306 | H2: 71573 | I2: 214719.1 | J2: 242467.1 | K2: 246300.1
A3: 標打 | B3: All Iscfm | C3: SEASONAL | D3: 67793.1 | E3: 14283.1 | F3: 5945.6 | G3: 2391.9 | H3: 5945.6 | I3: 17836.7 | J3: 17836.7 | K3: 17836.7
A4: 標打 | B4: All Iscfm | C4: SEASONAL-SWEATER | D4: 83453.6 | E4: 17995.6 | F4: 7273.1 | G4: 3449.4 | H4: 7273.1 | I4: 21819.3 | J4: 21819.3 | K4: 21819.3
A5: 標打 | B5: All Iscfm | C5: YEARLY RUN-304ALT | D5: 47150 | E5: 10250 | F5: 4100 | G5: 2050 | H5: 4100 | I5: 12300 | J5: 12300 | K5: 12300
A6: 標打 | B6: All Iscfm | C6: YEARLY RUN-ACT300 | D6: 481019.6 | E6: 92504.1 | F6: 37001.5 | G6: 18501.1 | H6: 37001.5 | I6: 111004.4 | J6: 138755.6 | K6: 138755.6
A7: 標打 | B7: All Iscfm | C7: YEARLY RUN-AIT350 | D7: 14640.2 | E7: 3544.6 | F7: 1232.8 | G7: 1078.9 | H7: 1232.8 | I7: 3698.5 | J7: 3698.5 | K7: 3698.5
